Workbook

Sheet 전체 통계
B2: 250918 | K2: 250918 | Q2: 공랭변화 | R2: 250918 | S2: 250929 | T2: 251006 | U2: 비고
B3: 상삼주 | C3: in600 | D3: in400 | E3: in200 | F3: in100 | G3: in50 | K3: 동맹 | L3: 전체분포 | M3: in140분포 | P3: 1 | Q3: 출항의날 | R3: =VLOOKUP('전체 통계'!$Q3,'하삼주(250918)'!$A$2:$D$315,3, FALSE) -> 7 | S3: =VLOOKUP('전체 통계'!$Q3,'하삼주 (250929)'!$A$2:$D$318,3, FALSE) -> 6 | T3: =VLOOKUP('전체 통계'!$Q3,'하삼주 (251006)'!$A$2:$D$313,3, FALSE) -> 5
B4: 잠룡 | C4: 191 | D4: 165 | E4: 117 | F4: 74 | G4: 41 | K4: 무명 | L4: 155 | M4: 90 | P4: 2 | Q4: 凵너구리 | R4: =VLOOKUP('전체 통계'!$Q4,'하삼주(250918)'!$A$2:$D$315,3, FALSE) -> 21 | S4: =VLOOKUP('전체 통계'!$Q4,'하삼주 (250929)'!$A$2:$D$318,3, FALSE) -> 12 | T4: =VLOOKUP('전체 통계'!$Q4,'하삼주 (251006)'!$A$2:$D$313,3, FALSE) -> 11
B5: 아이돌 | C5: 77 | D5: 34 | E5: 7 | F5: 2 | G5: 0 | K5: 혁명군 | L5: 115 | M5: 44 | P5: 3 | Q5: 必블리파파 | R5: =VLOOKUP('전체 통계'!$Q5,'하삼주(250918)'!$A$2:$D$315,3, FALSE) -> 11 | S5: =VLOOKUP('전체 통계'!$Q5,'하삼주 (250929)'!$A$2:$D$318,3, FALSE) -> 10 | T5: =VLOOKUP('전체 통계'!$Q5,'하삼주 (251006)'!$A$2:$D$313,3, FALSE) -> 13
B6: 협동조합 | C6: 12 | D6: 1 | E6: 0 | F6: 0 | G6: 0 | K6: 관중제장 | L6: 44 | M6: 6 | P6: 4 | Q6: 퍼플주에고 | R6: =VLOOKUP('전체 통계'!$Q6,'하삼주(250918)'!$A$2:$D$315,3, FALSE) -> 22 | S6: =VLOOKUP('전체 통계'!$Q6,'하삼주 (250929)'!$A$2:$D$318,3, FALSE) -> 19 | T6: =VLOOKUP('전체 통계'!$Q6,'하삼주 (251006)'!$A$2:$D$313,3, FALSE) -> 14
B7: 노동조합 | C7: 0 | D7: 0 | E7: 0 | F7: 0 | G7: 0 | K7: 250929 | P7: 5 | Q7: 흰밤 | R7: =VLOOKUP('전체 통계'!$Q7,'하삼주(250918)'!$A$2:$D$315,3, FALSE) -> 12 | S7: =VLOOKUP('전체 통계'!$Q7,'하삼주 (250929)'!$A$2:$D$318,3, FALSE) -> 14 | T7: =VLOOKUP('전체 통계'!$Q7,'하삼주 (251006)'!$A$2:$D$313,3, FALSE) -> 15
B8: 계 | C8: 280 | D8: 200 | E8: 124 | F8: 76 | G8: 41 | K8: 동맹 | L8: 전체분포 | M8: in140분포 | P8: 6 | Q8: 必비트핑 | R8: =VLOOKUP('전체 통계'!$Q8,'하삼주(250918)'!$A$2:$D$315,3, FALSE) -> 35 | S8: =VLOOKUP('전체 통계'!$Q8,'하삼주 (250929)'!$A$2:$D$318,3, FALSE) -> 20 | T8: =VLOOKUP('전체 통계'!$Q8,'하삼주 (251006)'!$A$2:$D$313,3, FALSE) -> 18
B9: 하삼주 | C9: in600 | D9: in400 | E9: in200 | F9: in100 | G9: in50 | K9: 무명 | L9: 150 | M9: 79 | P9: 7 | Q9: 컬러단장용스 | R9: =VLOOKUP('전체 통계'!$Q9,'하삼주(250918)'!$A$2:$D$315,3, FALSE) -> 30 | S9: =VLOOKUP('전체 통계'!$Q9,'하삼주 (250929)'!$A$2:$D$318,3, FALSE) -> 36 | T9: =VLOOKUP('전체 통계'!$Q9,'하삼주 (251006)'!$A$2:$D$313,3, FALSE) -> 32
B10: 무명 | C10: 155 | D10: 113 | E10: 52 | F10: 21 | G10: 9 | K10: 혁명군 | L10: 117 | M10: 54 | P10: 8 | Q10: 이직 | R10: =VLOOKUP('전체 통계'!$Q10,'하삼주(250918)'!$A$2:$D$315,3, FALSE) -> 44 | S10: =VLOOKUP('전체 통계'!$Q10,'하삼주 (250929)'!$A$2:$D$318,3, FALSE) -> 46 | T10: =VLOOKUP('전체 통계'!$Q10,'하삼주 (251006)'!$A$2:$D$313,3, FALSE) -> 38
B11: 혁명군 | C11: 115 | D11: 70 | E11: 23 | F11: 3 | G11: 0 | K11: 관중제장 | L11: 44 | M11: 7 | P11: 9 | Q11: SKELTON | R11: =VLOOKUP('전체 통계'!$Q11,'하삼주(250918)'!$A$2:$D$315,3, FALSE) -> 59 | S11: =VLOOKUP('전체 통계'!$Q11,'하삼주 (250929)'!$A$2:$D$318,3, FALSE) -> 45 | T11: =VLOOKUP('전체 통계'!$Q11,'하삼주 (251006)'!$A$2:$D$313,3, FALSE) -> 43
B12: 관중제장 | C12: 44 | D12: 15 | E12: 1 | F12: 0 | G12: 0 | K12: 251006 | P12: 10 | Q12: 羊양제 | R12: =VLOOKUP('전체 통계'!$Q12,'하삼주(250918)'!$A$2:$D$315,3, FALSE) -> 55 | S12: =VLOOKUP('전체 통계'!$Q12,'하삼주 (250929)'!$A$2:$D$318,3, FALSE) -> 58 | T12: =VLOOKUP('전체 통계'!$Q12,'하삼주 (251006)'!$A$2:$D$313,3, FALSE) -> 48
B13: 귀농단 | C13: 5 | D13: 2 | E13: 0 | F13: 0 | G13: 0 | K13: 동맹 | L13: 전체분포 | M13: in140분포 | P13: 11 | Q13: 羊마산동탁 | R13: =VLOOKUP('전체 통계'!$Q13,'하삼주(250918)'!$A$2:$D$315,3, FALSE) -> 61 | S13: =VLOOKUP('전체 통계'!$Q13,'하삼주 (250929)'!$A$2:$D$318,3, FALSE) -> 53 | T13: =VLOOKUP('전체 통계'!$Q13,'하삼주 (251006)'!$A$2:$D$313,3, FALSE) -> 50
B14: 계 | C14: 319 | D14: 200 | E14: 76 | F14: 24 | G14: 9 | K14: 무명 | L14: 146 | M14: 82 | P14: 12 | Q14: 爛추노꾼 | R14: =VLOOKUP('전체 통계'!$Q14,'하삼주(250918)'!$A$2:$D$315,3, FALSE) -> 47 | S14: =VLOOKUP('전체 통계'!$Q14,'하삼주 (250929)'!$A$2:$D$318,3, FALSE) -> 63 | T14: =VLOOKUP('전체 통계'!$Q14,'하삼주 (251006)'!$A$2:$D$313,3, FALSE) -> 65
B15: 250929 | K15: 혁명군 | L15: 120 | M15: 52 | P15: 13 | Q15: 必우마이봉 | R15: =VLOOKUP('전체 통계'!$Q15,'하삼주(250918)'!$A$2:$D$315,3, FALSE) -> 67 | S15: =VLOOKUP('전체 통계'!$Q15,'하삼주 (250929)'!$A$2:$D$318,3, FALSE) -> 71 | T15: =VLOOKUP('전체 통계'!$Q15,'하삼주 (251006)'!$A$2:$D$313,3, FALSE) -> 71
B16: 상삼주 | C16: in600 | D16: in400 | E16: in200 | F16: in100 | G16: in50 | K16: 관중제장 | L16: 41 | M16: 6 | P16: 16 | Q16: 羊고광렬 | R16: =VLOOKUP('전체 통계'!$Q18,'하삼주(250918)'!$A$2:$D$315,3, FALSE) -> 90 | S16: =VLOOKUP('전체 통계'!$Q18,'하삼주 (250929)'!$A$2:$D$318,3, FALSE) -> 77 | T16: =VLOOKUP('전체 통계'!$Q18,'하삼주 (251006)'!$A$2:$D$313,3, FALSE) -> 75
B17: 잠룡 | C17: 187 | D17: 161 | E17: 113 | F17: 68 | G17: 38 | P17: 14 | Q17: 必리나니 | R17: =VLOOKUP('전체 통계'!$Q16,'하삼주(250918)'!$A$2:$D$315,3, FALSE) -> 92 | S17: =VLOOKUP('전체 통계'!$Q16,'하삼주 (250929)'!$A$2:$D$318,3, FALSE) -> 86 | T17: =VLOOKUP('전체 통계'!$Q16,'하삼주 (251006)'!$A$2:$D$313,3, FALSE) -> 73
B18: 아이돌 | C18: 78 | D18: 41 | E18: 8 | F18: 3 | G18: 0 | P18: 15 | Q18: 凵진라면 | R18: =VLOOKUP('전체 통계'!$Q17,'하삼주(250918)'!$A$2:$D$315,3, FALSE) -> 62 | S18: =VLOOKUP('전체 통계'!$Q17,'하삼주 (250929)'!$A$2:$D$318,3, FALSE) -> 73 | T18: =VLOOKUP('전체 통계'!$Q17,'하삼주 (251006)'!$A$2:$D$313,3, FALSE) -> 74
B19: 협동조합 | C19: 17 | D19: 4 | E19: 0 | F19: 0 | G19: 0 | P19: 17 | Q19: 必비숍 | R19: =VLOOKUP('전체 통계'!$Q19,'하삼주(250918)'!$A$2:$D$315,3, FALSE) -> 111 | S19: =VLOOKUP('전체 통계'!$Q19,'하삼주 (250929)'!$A$2:$D$318,3, FALSE) -> 88 | T19: =VLOOKUP('전체 통계'!$Q19,'하삼주 (251006)'!$A$2:$D$313,3, FALSE) -> 76
B20: 노동조합 | C20: 1 | D20: 0 | E20: 0 | F20: 0 | G20: 0 | P20: 18 | Q20: 羊이정재 | R20: =VLOOKUP('전체 통계'!$Q20,'하삼주(250918)'!$A$2:$D$315,3, FALSE) -> 79 | S20: =VLOOKUP('전체 통계'!$Q20,'하삼주 (250929)'!$A$2:$D$318,3, FALSE) -> 76 | T20: =VLOOKUP('전체 통계'!$Q20,'하삼주 (251006)'!$A$2:$D$313,3, FALSE) -> 78
B21: 계 | C21: 283 | D21: 206 | E21: 121 | F21: 71 | G21: 38 | P21: 19 | Q21: 실직 | R21: =VLOOKUP('전체 통계'!$Q21,'하삼주(250918)'!$A$2:$D$315,3, FALSE) -> 68 | S21: =VLOOKUP('전체 통계'!$Q21,'하삼주 (250929)'!$A$2:$D$318,3, FALSE) -> 99 | T21: =VLOOKUP('전체 통계'!$Q21,'하삼주 (251006)'!$A$2:$D$313,3, FALSE) -> 101 | U21: 하락
B22: 하삼주 | C22: in600 | D22: in400 | E22: in200 | F22: in100 | G22: in50 | P22: 20 | Q22: 必써너 | R22: =VLOOKUP('전체 통계'!$Q22,'하삼주(250918)'!$A$2:$D$315,3, FALSE) -> 144 | S22: =VLOOKUP('전체 통계'!$Q22,'하삼주 (250929)'!$A$2:$D$318,3, FALSE) -> 134 | T22: =VLOOKUP('전체 통계'!$Q22,'하삼주 (251006)'!$A$2:$D$313,3, FALSE) -> 105
B23: 무명 | C23: 150 | D23: 107 | E23: 49 | F23: 20 | G23: 9 | P23: 21 | Q23: 羊현묘 | R23: =VLOOKUP('전체 통계'!$Q23,'하삼주(250918)'!$A$2:$D$315,3, FALSE) -> 85 | S23: =VLOOKUP('전체 통계'!$Q23,'하삼주 (250929)'!$A$2:$D$318,3, FALSE) -> 102 | T23: =VLOOKUP('전체 통계'!$Q23,'하삼주 (251006)'!$A$2:$D$313,3, FALSE) -> 111 | U23: 하락
B24: 혁명군 | C24: 117 | D24: 73 | E24: 27 | F24: 9 | G24: 3 | P24: 22 | Q24: 마룡의숲 | R24: =VLOOKUP('전체 통계'!$Q24,'하삼주(250918)'!$A$2:$D$315,3, FALSE) -> 82 | S24: =VLOOKUP('전체 통계'!$Q24,'하삼주 (250929)'!$A$2:$D$318,3, FALSE) -> 109 | T24: =VLOOKUP('전체 통계'!$Q24,'하삼주 (251006)'!$A$2:$D$313,3, FALSE) -> 121 | U24: 하락
B25: 관중제장 | C25: 44 | D25: 13 | E25: 3 | F25: 0 | G25: 0 | P25: 23 | Q25: 풍악의날 | R25: =VLOOKUP('전체 통계'!$Q25,'하삼주(250918)'!$A$2:$D$315,3, FALSE) -> 153 | S25: =VLOOKUP('전체 통계'!$Q25,'하삼주 (250929)'!$A$2:$D$318,3, FALSE) -> 145 | T25: =VLOOKUP('전체 통계'!$Q25,'하삼주 (251006)'!$A$2:$D$313,3, FALSE) -> 124
B26: 귀농단 | C26: 6 | D26: 1 | E26: 0 | F26: 0 | G26: 0 | P26: 24 | Q26: 너에게날 | R26: =VLOOKUP('전체 통계'!$Q26,'하삼주(250918)'!$A$2:$D$315,3, FALSE) -> 211 | S26: =VLOOKUP('전체 통계'!$Q26,'하삼주 (250929)'!$A$2:$D$318,3, FALSE) -> 143 | T26: =VLOOKUP('전체 통계'!$Q26,'하삼주 (251006)'!$A$2:$D$313,3, FALSE) -> 128 | U26: 범인
B27: 계 | C27: 317 | D27: 194 | E27: 79 | F27: 29 | G27: 12 | P27: 25 | Q27: 必폭주비비 | R27: =VLOOKUP('전체 통계'!$Q27,'하삼주(250918)'!$A$2:$D$315,3, FALSE) -> 123 | S27: =VLOOKUP('전체 통계'!$Q27,'하삼주 (250929)'!$A$2:$D$318,3, FALSE) -> 132 | T27: =VLOOKUP('전체 통계'!$Q27,'하삼주 (251006)'!$A$2:$D$313,3, FALSE) -> 132
B28: 251006 | P28: 26 | Q28: 羊서량철기 | R28: =VLOOKUP('전체 통계'!$Q28,'하삼주(250918)'!$A$2:$D$315,3, FALSE) -> 115 | S28: =VLOOKUP('전체 통계'!$Q28,'하삼주 (250929)'!$A$2:$D$318,3, FALSE) -> 146 | T28: =VLOOKUP('전체 통계'!$Q28,'하삼주 (251006)'!$A$2:$D$313,3, FALSE) -> 137
B29: 상삼주 | C29: in600 | D29: in400 | E29: in200 | F29: in100 | G29: in50 | P29: 29 | Q29: 必억까 | R29: =VLOOKUP('전체 통계'!$Q31,'하삼주(250918)'!$A$2:$D$315,3, FALSE) -> 158 | S29: =VLOOKUP('전체 통계'!$Q31,'하삼주 (250929)'!$A$2:$D$318,3, FALSE) -> 153 | T29: =VLOOKUP('전체 통계'!$Q31,'하삼주 (251006)'!$A$2:$D$313,3, FALSE) -> 150 | U29: 하락
B30: 잠룡 | C30: 188 | D30: 162 | E30: 116 | F30: 68 | G30: 35 | P30: 28 | Q30: 必무이 | R30: =VLOOKUP('전체 통계'!$Q30,'하삼주(250918)'!$A$2:$D$315,3, FALSE) -> 170 | S30: =VLOOKUP('전체 통계'!$Q30,'하삼주 (250929)'!$A$2:$D$318,3, FALSE) -> 148 | T30: =VLOOKUP('전체 통계'!$Q30,'하삼주 (251006)'!$A$2:$D$313,3, FALSE) -> 146
B31: 아이돌 | C31: 80 | D31: 43 | E31: 9 | F31: 3 | G31: 1 | P31: 27 | Q31: 爛해병 | R31: =VLOOKUP('전체 통계'!$Q29,'하삼주(250918)'!$A$2:$D$315,3, FALSE) -> 87 | S31: =VLOOKUP('전체 통계'!$Q29,'하삼주 (250929)'!$A$2:$D$318,3, FALSE) -> 91 | T31: =VLOOKUP('전체 통계'!$Q29,'하삼주 (251006)'!$A$2:$D$313,3, FALSE) -> 142
B32: 협동조합 | C32: 19 | D32: 4 | E32: 0 | F32: 0 | G32: 0 | P32: 30 | Q32: 必보이쓰피싱 | R32: =VLOOKUP('전체 통계'!$Q32,'하삼주(250918)'!$A$2:$D$315,3, FALSE) -> 201 | S32: =VLOOKUP('전체 통계'!$Q32,'하삼주 (250929)'!$A$2:$D$318,3, FALSE) -> 171 | T32: =VLOOKUP('전체 통계'!$Q32,'하삼주 (251006)'!$A$2:$D$313,3, FALSE) -> 151
B33: 노동조합 | C33: 1 | D33: 0 | E33: 0 | F33: 0 | G33: 0 | P33: 31 | Q33: 싸나이흑운 | R33: =VLOOKUP('전체 통계'!$Q33,'하삼주(250918)'!$A$2:$D$315,3, FALSE) -> 132 | S33: =VLOOKUP('전체 통계'!$Q33,'하삼주 (250929)'!$A$2:$D$318,3, FALSE) -> 147 | T33: =VLOOKUP('전체 통계'!$Q33,'하삼주 (251006)'!$A$2:$D$313,3, FALSE) -> 153
B34: 계 | C34: 288 | D34: 209 | E34: 125 | F34: 71 | G34: 36 | P34: 32 | Q34: 폭우의날 | R34: =VLOOKUP('전체 통계'!$Q34,'하삼주(250918)'!$A$2:$D$315,3, FALSE) -> 192 | S34: =VLOOKUP('전체 통계'!$Q34,'하삼주 (250929)'!$A$2:$D$318,3, FALSE) -> 154 | T34: =VLOOKUP('전체 통계'!$Q34,'하삼주 (251006)'!$A$2:$D$313,3, FALSE) -> 156
B35: 하삼주 | C35: in600 | D35: in400 | E35: in200 | F35: in100 | G35: in50 | P35: 33 | Q35: 羊농민 | R35: =VLOOKUP('전체 통계'!$Q35,'하삼주(250918)'!$A$2:$D$315,3, FALSE) -> 137 | S35: =VLOOKUP('전체 통계'!$Q35,'하삼주 (250929)'!$A$2:$D$318,3, FALSE) -> 173 | T35: =VLOOKUP('전체 통계'!$Q35,'하삼주 (251006)'!$A$2:$D$313,3, FALSE) -> 159
B36: 무명 | C36: 146 | D36: 106 | E36: 48 | F36: 18 | G36: 11 | P36: 34 | Q36: 爛밤 | R36: =VLOOKUP('전체 통계'!$Q36,'하삼주(250918)'!$A$2:$D$315,3, FALSE) -> 126 | S36: =VLOOKUP('전체 통계'!$Q36,'하삼주 (250929)'!$A$2:$D$318,3, FALSE) -> 151 | T36: =VLOOKUP('전체 통계'!$Q36,'하삼주 (251006)'!$A$2:$D$313,3, FALSE) -> 161 | U36: 하락
B37: 혁명군 | C37: 120 | D37: 72 | E37: 25 | F37: 11 | G37: 3 | P37: 36 | Q37: 必귀살대 | R37: =VLOOKUP('전체 통계'!$Q38,'하삼주(250918)'!$A$2:$D$315,3, FALSE) -> 146 | S37: =VLOOKUP('전체 통계'!$Q38,'하삼주 (250929)'!$A$2:$D$318,3, FALSE) -> 169 | T37: =VLOOKUP('전체 통계'!$Q38,'하삼주 (251006)'!$A$2:$D$313,3, FALSE) -> 169
B38: 관중제장 | C38: 41 | D38: 12 | E38: 2 | F38: 0 | G38: 0 | P38: 35 | Q38: 헁기싫어 | R38: =VLOOKUP('전체 통계'!$Q37,'하삼주(250918)'!$A$2:$D$315,3, FALSE) -> 166 | S38: =VLOOKUP('전체 통계'!$Q37,'하삼주 (250929)'!$A$2:$D$318,3, FALSE) -> 178 | T38: =VLOOKUP('전체 통계'!$Q37,'하삼주 (251006)'!$A$2:$D$313,3, FALSE) -> 167
B39: 귀농단 | C39: 5 | D39: 1 | E39: 0 | F39: 0 | G39: 0 | P39: 37 | Q39: 주님곁으로 | R39: =VLOOKUP('전체 통계'!$Q39,'하삼주(250918)'!$A$2:$D$315,3, FALSE) -> 220 | S39: =VLOOKUP('전체 통계'!$Q39,'하삼주 (250929)'!$A$2:$D$318,3, FALSE) -> 172 | T39: =VLOOKUP('전체 통계'!$Q39,'하삼주 (251006)'!$A$2:$D$313,3, FALSE) -> 170
B40: 계 | C40: 312 | D40: 191 | E40: 75 | F40: 29 | G40: 14 | P40: 38 | Q40: 기파랑해 | R40: =VLOOKUP('전체 통계'!$Q40,'하삼주(250918)'!$A$2:$D$315,3, FALSE) -> 206 | S40: =VLOOKUP('전체 통계'!$Q40,'하삼주 (250929)'!$A$2:$D$318,3, FALSE) -> 192 | T40: =VLOOKUP('전체 통계'!$Q40,'하삼주 (251006)'!$A$2:$D$313,3, FALSE) -> 172
P41: 39 | Q41: 羊알부장 | R41: =VLOOKUP('전체 통계'!$Q41,'하삼주(250918)'!$A$2:$D$315,3, FALSE) -> 163 | S41: =VLOOKUP('전체 통계'!$Q41,'하삼주 (250929)'!$A$2:$D$318,3, FALSE) -> 175 | T41: =VLOOKUP('전체 통계'!$Q41,'하삼주 (251006)'!$A$2:$D$313,3, FALSE) -> 174
...

Sheet 전체 랭킹 (251123)
C1: 우삼주 | D1: in600 | E1: in400 | F1: in200 | G1: in100 | H1: in50
C2: 퍼스트 | D2: =COUNTIF($C$14:$C$613,$C2) -> 172 | E2: =COUNTIF($C$14:$C$413,$C2) -> 158 | F2: =COUNTIF($C$14:$C$213,$C2) -> 101 | G2: =COUNTIF($C$14:$C$113,$C2) -> 58 | H2: =COUNTIF($C$14:$C$63,$C2) -> 33 | J2: 緣 | K2: 緣
C3: 세컨드 | D3: =COUNTIF($C$14:$C$613,$C3) -> 62 | E3: =COUNTIF($C$14:$C$413,$C3) -> 27 | F3: =COUNTIF($C$14:$C$213,$C3) -> 6 | G3: =COUNTIF($C$14:$C$113,$C3) -> 3 | H3: =COUNTIF($C$14:$C$63,$C3) -> 1 | J3: 少林 | K3: 少林
C4: 서드 | D4: =COUNTIF($C$14:$C$613,$C4) -> 43 | E4: =COUNTIF($C$14:$C$413,$C4) -> 16 | F4: =COUNTIF($C$14:$C$213,$C4) -> 5 | G4: =COUNTIF($C$14:$C$113,$C4) -> 0 | H4: =COUNTIF($C$14:$C$63,$C4) -> 0 | J4: 乄 | K4: 乄
C5: 심슨 | D5: =COUNTIF($C$14:$C$613,$C5) -> 2 | E5: =COUNTIF($C$14:$C$413,$C5) -> 0 | F5: =COUNTIF($C$14:$C$213,$C5) -> 0 | G5: =COUNTIF($C$14:$C$113,$C5) -> 0 | H5: =COUNTIF($C$14:$C$63,$C5) -> 0 | J5: 凵 | K5: 凵
C6: 계 | D6: =SUM(D2:D5) -> 279 | E6: =SUM(E2:E5) -> 201 | F6: =SUM(F2:F5) -> 112 | G6: =SUM(G2:G5) -> 61 | H6: =SUM(H2:H5) -> 34
C7: 좌삼주 | D7: in600 | E7: in400 | F7: in200 | G7: in100 | H7: in50
C8: 무명 | D8: =COUNTIF($C$14:$C$613,$C8) -> 157 | E8: =COUNTIF($C$14:$C$413,$C8) -> 114 | F8: =COUNTIF($C$14:$C$213,$C8) -> 58 | G8: =COUNTIF($C$14:$C$113,$C8) -> 30 | H8: =COUNTIF($C$14:$C$63,$C8) -> 12
C9: 야신 | D9: =COUNTIF($C$14:$C$613,$C9) -> 98 | E9: =COUNTIF($C$14:$C$413,$C9) -> 57 | F9: =COUNTIF($C$14:$C$213,$C9) -> 23 | G9: =COUNTIF($C$14:$C$113,$C9) -> 8 | H9: =COUNTIF($C$14:$C$63,$C9) -> 3
C10: 팔건장 | D10: =COUNTIF($C$14:$C$613,$C10) -> 66 | E10: =COUNTIF($C$14:$C$413,$C10) -> 28 | F10: =COUNTIF($C$14:$C$213,$C10) -> 7 | G10: =COUNTIF($C$14:$C$113,$C10) -> 1 | H10: =COUNTIF($C$14:$C$63,$C10) -> 1
D11: =COUNTIF($C$14:$C$613,$C11) -> 0 | E11: =COUNTIF($C$14:$C$413,$C11) -> 0 | F11: =COUNTIF($C$14:$C$213,$C11) -> 0 | G11: =COUNTIF($C$14:$C$113,$C11) -> 0 | H11: =COUNTIF($C$14:$C$63,$C11) -> 0
C12: 계 | D12: =SUM(D8:D11) -> 321 | E12: =SUM(E8:E11) -> 199 | F12: =SUM(F8:F11) -> 88 | G12: =SUM(G8:G11) -> 39 | H12: =SUM(H8:H11) -> 16
A13: 랭킹 | B13: 이름 | C13: 동맹
A14: 1 | B14: 파트리샤 | C14: 퍼스트
A15: 2 | B15: 勇에넥스 | C15: 퍼스트
A16: 3 | B16: 十빌립 | C16: 퍼스트
A17: 4 | B17: ST자칼 | C17: 무명
A18: 5 | B18: 투신백초 | C18: 야신
A19: 6 | B19: 勇수정 | C19: 퍼스트
A20: 7 | B20: 유재휘 | C20: 퍼스트
A21: 8 | B21: 花마크 | C21: 퍼스트
A22: 9 | B22: 아키쨩 | C22: 퍼스트
A23: 10 | B23: 손절기석 | C23: 퍼스트
A24: 11 | B24: ST미췬팩폭 | C24: 무명
A25: 12 | B25: 麗쏘다 | C25: 야신
... A613: 600 | B613: 어머님 | C613: 세컨드

Sheet 하삼주(250918)
A1: 이름 | B1: 동맹 | C1: 랭킹 | D1: 진영 순위 | F1: 동맹 | G1: 전체분포 | H1: in140분포
A2: 출항의날 | B2: 무명 | C2: 7 | D2: 1 | F2: 무명 | G2: =COUNTIF($B$2:$B$315,$F2) -> 155 | H2: =COUNTIF($B$2:$B$141,$F2) -> 90
A3: 必블리파파 | B3: 무명 | C3: 11 | D3: 2 | F3: 혁명군 | G3: =COUNTIF($B$2:$B$315,$F3) -> 115 | H3: =COUNTIF($B$2:$B$141,$F3) -> 44
A4: 흰밤 | B4: 무명 | C4: 12 | D4: 3 | F4: 관중제장 | G4: =COUNTIF($B$2:$B$315,$F4) -> 44 | H4: =COUNTIF($B$2:$B$141,$F4) -> 6
A5: 凵너구리 | B5: 무명 | C5: 21 | D5: 4
A6: 퍼플주에고 | B6: 무명 | C6: 22 | D6: 5
A7: 컬러단장용스 | B7: 무명 | C7: 30 | D7: 6 | F7: 출항의날 | G7: =VLOOKUP(F7,A2:D315,1,FALSE) -> 출항의날
A8: 必비트핑 | B8: 무명 | C8: 35 | D8: 7
A9: 이직 | B9: 무명 | C9: 44 | D9: 8
A10: 爛추노꾼 | B10: 무명 | C10: 47 | D10: 9
A11: 羊양제 | B11: 무명 | C11: 55 | D11: 10
A12: SKELTON | B12: 무명 | C12: 59 | D12: 11
A13: 羊마산동탁 | B13: 무명 | C13: 61 | D13: 12
A14: 必리나니 | B14: 무명 | C14: 62 | D14: 13
A15: 必우마이봉 | B15: 무명 | C15: 67 | D15: 14
A16: 실직 | B16: 무명 | C16: 68 | D16: 15
A17: 乄애램 | B17: 혁명군 | C17: 72 | D17: 16
A18: 羊이정재 | B18: 무명 | C18: 79 | D18: 17
A19: 마룡의숲 | B19: 무명 | C19: 82 | D19: 18
... A315: 超연격초토화 | B315: 관중제장 | C315: 600 | D315: 314

Sheet 전체 랭킹 (250929)
D1: 상삼주 | E1: in600 | F1: in400 | G1: in200 | H1: in100 | I1: in50
D2: 잠룡 | E2: =COUNTIF($C$14:$C$613,$D2) -> 187 | F2: =COUNTIF($C$14:$C$413,$D2) -> 161 | G2: =COUNTIF($C$14:$C$213,$D2) -> 113 | H2: =COUNTIF($C$14:$C$113,$D2) -> 68 | I2: =COUNTIF($C$14:$C$63,$D2) -> 38 | O2: 每 | P2: 매 | Q2: 每
D3: 아이돌 | E3: =COUNTIF($C$14:$C$613,$D3) -> 78 | F3: =COUNTIF($C$14:$C$413,$D3) -> 41 | G3: =COUNTIF($C$14:$C$213,$D3) -> 8 | H3: =COUNTIF($C$14:$C$113,$D3) -> 3 | I3: =COUNTIF($C$14:$C$63,$D3) -> 0 | O3: 天威 | P3: 天威 | Q3: 天威
D4: 협동조합 | E4: =COUNTIF($C$14:$C$613,$D4) -> 17 | F4: =COUNTIF($C$14:$C$413,$D4) -> 4 | G4: =COUNTIF($C$14:$C$213,$D4) -> 0 | H4: =COUNTIF($C$14:$C$113,$D4) -> 0 | I4: =COUNTIF($C$14:$C$63,$D4) -> 0 | O4: 丫 | P4: 아 | Q4: 丫
D5: 노동조합 | E5: =COUNTIF($C$14:$C$613,$D5) -> 1 | F5: =COUNTIF($C$14:$C$413,$D5) -> 0 | G5: =COUNTIF($C$14:$C$213,$D5) -> 0 | H5: =COUNTIF($C$14:$C$113,$D5) -> 0 | I5: =COUNTIF($C$14:$C$63,$D5) -> 0 | O5: 乄 | P5: 오 | Q5: 乄
D6: 계 | E6: =SUM(E2:E5) -> 283 | F6: =SUM(F2:F5) -> 206 | G6: =SUM(G2:G5) -> 121 | H6: =SUM(H2:H5) -> 71 | I6: =SUM(I2:I5) -> 38 | O6: 忠義 | P6: 忠義 | Q6: 忠義
D7: 하삼주 | E7: in600 | F7: in400 | G7: in200 | H7: in100 | I7: in50 | O7: 遊興 | P7: 遊興 | Q7: 遊興
D8: 무명 | E8: =COUNTIF($C$14:$C$613,$D8) -> 150 | F8: =COUNTIF($C$14:$C$413,$D8) -> 107 | G8: =COUNTIF($C$14:$C$213,$D8) -> 49 | H8: =COUNTIF($C$14:$C$113,$D8) -> 20 | I8: =COUNTIF($C$14:$C$63,$D8) -> 9 | O8: 亗 | P8: 세 | Q8: 亗
D9: 혁명군 | E9: =COUNTIF($C$14:$C$613,$D9) -> 117 | F9: =COUNTIF($C$14:$C$413,$D9) -> 73 | G9: =COUNTIF($C$14:$C$213,$D9) -> 27 | H9: =COUNTIF($C$14:$C$113,$D9) -> 9 | I9: =COUNTIF($C$14:$C$63,$D9) -> 3 | O9: 凵 | P9: 감 | Q9: 凵
D10: 관중제장 | E10: =COUNTIF($C$14:$C$613,$D10) -> 44 | F10: =COUNTIF($C$14:$C$413,$D10) -> 13 | G10: =COUNTIF($C$14:$C$213,$D10) -> 3 | H10: =COUNTIF($C$14:$C$113,$D10) -> 0 | I10: =COUNTIF($C$14:$C$63,$D10) -> 0
D11: 귀농단 | E11: =COUNTIF($C$14:$C$613,$D11) -> 6 | F11: =COUNTIF($C$14:$C$413,$D11) -> 1 | G11: =COUNTIF($C$14:$C$213,$D11) -> 0 | H11: =COUNTIF($C$14:$C$113,$D11) -> 0 | I11: =COUNTIF($C$14:$C$63,$D11) -> 0
D12: 계 | E12: =SUM(E8:E11) -> 317 | F12: =SUM(F8:F11) -> 194 | G12: =SUM(G8:G11) -> 79 | H12: =SUM(H8:H11) -> 29 | I12: =SUM(I8:I11) -> 12
A13: 랭킹 | B13: 이름 | C13: 동맹
A14: 1 | B14: 天威아조씨 | C14: 잠룡
A15: 2 | B15: 靑핑돌 | C15: 잠룡
A16: 3 | B16: 황금비 | C16: 잠룡
A17: 4 | B17: 이로아 | C17: 잠룡
A18: 5 | B18: 붉은윈터 | C18: 잠룡
A19: 6 | B19: 출항의날 | C19: 무명
A20: 7 | B20: 소풍온아모림 | C20: 잠룡
A21: 8 | B21: 돌격사신 | C21: 잠룡
A22: 9 | B22: 화요싫어 | C22: 잠룡
A23: 10 | B23: 必블리파파 | C23: 무명
A24: 11 | B24: 靑세쥬 | C24: 잠룡
A25: 12 | B25: 凵너구리 | C25: 무명
... A613: 600 | B613: 슈육한날 | C613: 무명

Sheet 하삼주 (250929)
A1: 이름 | B1: 동맹 | C1: 랭킹 | D1: 진영 순위 | F1: 동맹 | G1: 전체분포 | H1: in140분포
A2: 출항의날 | B2: 무명 | C2: 6 | D2: 1 | F2: 무명 | G2: =COUNTIF($B$2:$B$318,$F2) -> 150 | H2: =COUNTIF($B$2:$B$141,$F2) -> 79
A3: 必블리파파 | B3: 무명 | C3: 10 | D3: 2 | F3: 혁명군 | G3: =COUNTIF($B$2:$B$318,$F3) -> 117 | H3: =COUNTIF($B$2:$B$141,$F3) -> 54
A4: 凵너구리 | B4: 무명 | C4: 12 | D4: 3 | F4: 관중제장 | G4: =COUNTIF($B$2:$B$318,$F4) -> 44 | H4: =COUNTIF($B$2:$B$141,$F4) -> 7
A5: 흰밤 | B5: 무명 | C5: 14 | D5: 4 | E5: 컬러단
A6: 퍼플주에고 | B6: 무명 | C6: 19 | D6: 5 | E6: 컬러단
A7: 必비트핑 | B7: 무명 | C7: 20 | D7: 6
A8: 乄애램 | B8: 혁명군 | C8: 23 | D8: 7
A9: 컬러단장용스 | B9: 무명 | C9: 36 | D9: 8 | E9: 컬러단
A10: W레젠디아 | B10: 혁명군 | C10: 38 | D10: 9
A11: W라기 | B11: 혁명군 | C11: 40 | D11: 10
A12: SKELTON | B12: 무명 | C12: 45 | D12: 11
A13: 이직 | B13: 무명 | C13: 46 | D13: 12
A14: 羊마산동탁 | B14: 무명 | C14: 53 | D14: 13
A15: 羊양제 | B15: 무명 | C15: 58 | D15: 14
A16: 爛추노꾼 | B16: 무명 | C16: 63 | D16: 15
A17: 必우마이봉 | B17: 무명 | C17: 71 | D17: 16
A18: 必리나니 | B18: 무명 | C18: 73 | D18: 17
A19: 羊이정재 | B19: 무명 | C19: 76 | D19: 18
A20: 凵진라면 | B20: 무명 | C20: 77 | D20: 19
A21: 麗호우 | B21: 혁명군 | C21: 78 | D21: 20
... A68: 적색의용 | B68: 관중제장 | C68: 183 | D68: 67
A69: 흰밥 | B69: 무명 | C69: 184 | D69: 68 | E69: 컬러단
A70: 羊마속 | B70: 무명 | C70: 186 | D70: 69
A71: GP또또 | B71: 관중제장 | C71: 187 | D71: 70
A72: 羊열하 | B72: 무명 | C72: 189 | D72: 71
A73: 최경주 | B73: 무명 | C73: 191 | D73: 72
A74: 기파랑해 | B74: 무명 | C74: 192 | D74: 73
A75: SP제갈공명 | B75: 혁명군 | C75: 193 | D75: 74
A76: 어른이날 | B76: 무명 | C76: 195 | D76: 75
A77: 싸나이가는길 | B77: 무명 | C77: 196 | D77: 76
A78: Fins | B78: 혁명군 | C78: 197 | D78: 77
A79: Ak동 | B79: 무명 | C79: 198 | D79: 78
A80: 羊관우 | B80: 무명 | C80: 200 | D80: 79
A81: 必인삼 | B81: 무명 | C81: 204 | D81: 80
... A94: 必설리 | B94: 무명 | C94: 223 | D94: 93
A95: 바나나 | B95: 무명 | C95: 224 | D95: 94 | E95: 컬러단
A96: 羊마형 | B96: 무명 | C96: 225 | D96: 95
A97: 멍멍도깨비 | B97: 관중제장 | C97: 226 | D97: 96
A98: 내미시스 | B98: 무명 | C98: 233 | D98: 97
...

Sheet 전체 랭킹 (251006)
D1: 상삼주 | E1: in600 | F1: in400 | G1: in200 | H1: in100 | I1: in50
D2: 잠룡 | E2: =COUNTIF($C$14:$C$613,$D2) -> 188 | F2: =COUNTIF($C$14:$C$413,$D2) -> 162 | G2: =COUNTIF($C$14:$C$213,$D2) -> 116 | H2: =COUNTIF($C$14:$C$113,$D2) -> 68 | I2: =COUNTIF($C$14:$C$63,$D2) -> 35 | O2: 每 | P2: 매 | Q2: 每
D3: 아이돌 | E3: =COUNTIF($C$14:$C$613,$D3) -> 80 | F3: =COUNTIF($C$14:$C$413,$D3) -> 43 | G3: =COUNTIF($C$14:$C$213,$D3) -> 9 | H3: =COUNTIF($C$14:$C$113,$D3) -> 3 | I3: =COUNTIF($C$14:$C$63,$D3) -> 1 | O3: 天威 | P3: 天威 | Q3: 天威
D4: 협동조합 | E4: =COUNTIF($C$14:$C$613,$D4) -> 19 | F4: =COUNTIF($C$14:$C$413,$D4) -> 4 | G4: =COUNTIF($C$14:$C$213,$D4) -> 0 | H4: =COUNTIF($C$14:$C$113,$D4) -> 0 | I4: =COUNTIF($C$14:$C$63,$D4) -> 0 | O4: 丫 | P4: 아 | Q4: 丫
D5: 노동조합 | E5: =COUNTIF($C$14:$C$613,$D5) -> 1 | F5: =COUNTIF($C$14:$C$413,$D5) -> 0 | G5: =COUNTIF($C$14:$C$213,$D5) -> 0 | H5: =COUNTIF($C$14:$C$113,$D5) -> 0 | I5: =COUNTIF($C$14:$C$63,$D5) -> 0 | O5: 乄 | P5: 오 | Q5: 乄
B6: 义 | D6: 계 | E6: =SUM(E2:E5) -> 288 | F6: =SUM(F2:F5) -> 209 | G6: =SUM(G2:G5) -> 125 | H6: =SUM(H2:H5) -> 71 | I6: =SUM(I2:I5) -> 36 | O6: 忠義 | P6: 忠義 | Q6: 忠義
D7: 하삼주 | E7: in600 | F7: in400 | G7: in200 | H7: in100 | I7: in50 | O7: 遊興 | P7: 遊興 | Q7: 遊興
D8: 무명 | E8: =COUNTIF($C$14:$C$613,$D8) -> 146 | F8: =COUNTIF($C$14:$C$413,$D8) -> 106 | G8: =COUNTIF($C$14:$C$213,$D8) -> 48 | H8: =COUNTIF($C$14:$C$113,$D8) -> 18 | I8: =COUNTIF($C$14:$C$63,$D8) -> 11 | O8: 亗 | P8: 세 | Q8: 亗
D9: 혁명군 | E9: =COUNTIF($C$14:$C$613,$D9) -> 120 | F9: =COUNTIF($C$14:$C$413,$D9) -> 72 | G9: =COUNTIF($C$14:$C$213,$D9) -> 25 | H9: =COUNTIF($C$14:$C$113,$D9) -> 11 | I9: =COUNTIF($C$14:$C$63,$D9) -> 3 | O9: 凵 | P9: 감 | Q9: 凵
D10: 관중제장 | E10: =COUNTIF($C$14:$C$613,$D10) -> 41 | F10: =COUNTIF($C$14:$C$413,$D10) -> 12 | G10: =COUNTIF($C$14:$C$213,$D10) -> 2 | H10: =COUNTIF($C$14:$C$113,$D10) -> 0 | I10: =COUNTIF($C$14:$C$63,$D10) -> 0
D11: 귀농단 | E11: =COUNTIF($C$14:$C$613,$D11) -> 5 | F11: =COUNTIF($C$14:$C$413,$D11) -> 1 | G11: =COUNTIF($C$14:$C$213,$D11) -> 0 | H11: =COUNTIF($C$14:$C$113,$D11) -> 0 | I11: =COUNTIF($C$14:$C$63,$D11) -> 0
D12: 계 | E12: =SUM(E8:E11) -> 312 | F12: =SUM(F8:F11) -> 191 | G12: =SUM(G8:G11) -> 75 | H12: =SUM(H8:H11) -> 29 | I12: =SUM(I8:I11) -> 14
A13: 랭킹 | B13: 이름 | C13: 동맹
A14: 1 | B14: 天威아조씨 | C14: 잠룡
A15: 2 | B15: 靑핑돌 | C15: 잠룡
A16: 3 | B16: 황금비 | C16: 잠룡
A17: 4 | B17: 이로아 | C17: 잠룡
A18: 5 | B18: 출항의날 | C18: 무명
A19: 6 | B19: 소풍온아모림 | C19: 잠룡
A20: 7 | B20: 돌격사신 | C20: 잠룡
A21: 8 | B21: 화요싫어 | C21: 잠룡
A22: 9 | B22: 붉은윈터 | C22: 잠룡
A23: 10 | B23: 龍오마카세 | C23: 잠룡
A24: 11 | B24: 凵너구리 | C24: 무명
A25: 12 | B25: 靑세쥬 | C25: 잠룡
... A613: 600 | B613: 하늘물괴기 | C613: 아이돌

Sheet 하삼주 (251006)
A1: 이름 | B1: 동맹 | C1: 랭킹 | D1: 진영 순위 | F1: 동맹 | G1: 전체분포 | H1: in140분포
A2: 출항의날 | B2: 무명 | C2: 5 | D2: 1 | F2: 무명 | G2: =COUNTIF($B$2:$B$313,$F2) -> 145 | H2: =COUNTIF($B$2:$B$61,$F2) -> 35
A3: 凵너구리 | B3: 무명 | C3: 11 | D3: 2 | F3: 혁명군 | G3: =COUNTIF($B$2:$B$313,$F3) -> 120 | H3: =COUNTIF($B$2:$B$61,$F3) -> 23
A4: 必블리파파 | B4: 무명 | C4: 13 | D4: 3 | F4: 관중제장 | G4: =COUNTIF($B$2:$B$313,$F4) -> 41 | H4: =COUNTIF($B$2:$B$61,$F4) -> 2
A5: 퍼플주에고 | B5: 무명 | C5: 14 | D5: 4
A6: 흰밤 | B6: 무명 | C6: 15 | D6: 5
A7: 必비트핑 | B7: 무명 | C7: 18 | D7: 6
A8: 乄애램 | B8: 혁명군 | C8: 20 | D8: 7
A9: W레젠디아 | B9: 혁명군 | C9: 31 | D9: 8
A10: 컬러단장용스 | B10: 무명 | C10: 32 | D10: 9
A11: W라기 | B11: 혁명군 | C11: 37 | D11: 10
A12: 이직 | B12: 무명 | C12: 38 | D12: 11
A13: SKELTON | B13: 무명 | C13: 43 | D13: 12
A14: 羊양제 | B14: 무명 | C14: 48 | D14: 13
A15: 羊마산동탁 | B15: 무명 | C15: 50 | D15: 14
A16: 爛추노꾼 | B16: 무명 | C16: 65 | D16: 15
... A193: 乄탕구리 | B193: 혁명군 | C193: 402 | D193: 192
A194: 무무 | B194: 무명 | C194: 405 | D194: 193 | E194: 주식
A195: 불눈이tv | B195: 무명 | C195: 407 | D195: 194 | E195: 양침
A196: 콥관음병 | B196: 무명 | C196: 408 | D196: 195 | E196: 양침
A197: 乄미리내 | B197: 혁명군 | C197: 409 | D197: 196
A198: 흰방 | B198: 무명 | C198: 411 | D198: 197 | E198: 양침
A199: W취자 | B199: 혁명군 | C199: 413 | D199: 198
A200: Mx야마토 | B200: 관중제장 | C200: 420 | D200: 199
A201: 虎초격차 | B201: 혁명군 | C201: 421 | D201: 200
A202: Mx허갈 | B202: 관중제장 | C202: 422 | D202: 201
A203: 必애리 | B203: 무명 | C203: 423 | D203: 202 | E203: 괴도
A204: 乄옴걸 | B204: 혁명군 | C204: 425 | D204: 203
A205: Beluga | B205: 혁명군 | C205: 426 | D205: 204
A206: 乄목재수비군 | B206: 혁명군 | C206: 428 | D206: 205
A207: 폐월 | B207: 관중제장 | C207: 429 | D207: 206
A208: 羊여름이다 | B208: 무명 | C208: 430 | D208: 207 | E208: 양침
A209: 글램핑 | B209: 무명 | C209: 432 | D209: 208 | E209: 주식
A210: 虎모래성 | B210: 혁명군 | C210: 433 | D210: 209
A211: 광색의용 | B211: 관중제장 | C211: 435 | D211: 210
A212: 乄공터수비군 | B212: 혁명군 | C212: 436 | D212: 211
A213: 금색의용 | B213: 관중제장 | C213: 437 | D213: 212
A214: 눈오던날 | B214: 무명 | C214: 438 | D214: 213 | E214: 날
A215: 성룡 | B215: 무명 | C215: 439 | D215: 214 | E215: 주식
A216: 凵참깨라면 | B216: 무명 | C216: 440 | D216: 215 | E216: 양침
...
