Workbook

Sheet 전체 통계
B2: 250918 | K2: 250918 | Q2: 공랭변화 | R2: 250918 | S2: 250929 | T2: 251006 | U2: 비고
B3: 상삼주 | C3: in600 | D3: in400 | E3: in200 | F3: in100 | G3: in50 | K3: 동맹 | L3: 전체분포 | M3: in140분포 | P3: 1 | Q3: 출항의날 | R3: =VLOOKUP('전체 통계'!$Q3,'하삼주(250918)'!$A$2:$D$315,3, FALSE) -> 7 | S3: =VLOOKUP('전체 통계'!$Q3,'하삼주 (250929)'!$A$2:$D$318,3, FALSE) -> 6 | T3: =VLOOKUP('전체 통계'!$Q3,'하삼주 (251006)'!$A$2:$D$313,3, FALSE) -> 5
B4: 잠룡 | C4: 191 | D4: 165 | E4: 117 | F4: 74 | G4: 41 | K4: 무명 | L4: 155 | M4: 90 | P4: 2 | Q4: 凵너구리 | R4: =VLOOKUP('전체 통계'!$Q4,'하삼주(250918)'!$A$2:$D$315,3, FALSE) -> 21 | S4: =VLOOKUP('전체 통계'!$Q4,'하삼주 (250929)'!$A$2:$D$318,3, FALSE) -> 12 | T4: =VLOOKUP('전체 통계'!$Q4,'하삼주 (251006)'!$A$2:$D$313,3, FALSE) -> 11
B5: 아이돌 | C5: 77 | D5: 34 | E5: 7 | F5: 2 | G5: 0 | K5: 혁명군 | L5: 115 | M5: 44 | P5: 3 | Q5: 必블리파파 | R5: =VLOOKUP('전체 통계'!$Q5,'하삼주(250918)'!$A$2:$D$315,3, FALSE) -> 11 | S5: =VLOOKUP('전체 통계'!$Q5,'하삼주 (250929)'!$A$2:$D$318,3, FALSE) -> 10 | T5: =VLOOKUP('전체 통계'!$Q5,'하삼주 (251006)'!$A$2:$D$313,3, FALSE) -> 13
B6: 협동조합 | C6: 12 | D6: 1 | E6: 0 | F6: 0 | G6: 0 | K6: 관중제장 | L6: 44 | M6: 6 | P6: 4 | Q6: 퍼플주에고 | R6: =VLOOKUP('전체 통계'!$Q6,'하삼주(250918)'!$A$2:$D$315,3, FALSE) -> 22 | S6: =VLOOKUP('전체 통계'!$Q6,'하삼주 (250929)'!$A$2:$D$318,3, FALSE) -> 19 | T6: =VLOOKUP('전체 통계'!$Q6,'하삼주 (251006)'!$A$2:$D$313,3, FALSE) -> 14
B7: 노동조합 | C7: 0 | D7: 0 | E7: 0 | F7: 0 | G7: 0 | K7: 250929 | P7: 5 | Q7: 흰밤 | R7: =VLOOKUP('전체 통계'!$Q7,'하삼주(250918)'!$A$2:$D$315,3, FALSE) -> 12 | S7: =VLOOKUP('전체 통계'!$Q7,'하삼주 (250929)'!$A$2:$D$318,3, FALSE) -> 14 | T7: =VLOOKUP('전체 통계'!$Q7,'하삼주 (251006)'!$A$2:$D$313,3, FALSE) -> 15
B8: 계 | C8: 280 | D8: 200 | E8: 124 | F8: 76 | G8: 41 | K8: 동맹 | L8: 전체분포 | M8: in140분포 | P8: 6 | Q8: 必비트핑 | R8: =VLOOKUP('전체 통계'!$Q8,'하삼주(250918)'!$A$2:$D$315,3, FALSE) -> 35 | S8: =VLOOKUP('전체 통계'!$Q8,'하삼주 (250929)'!$A$2:$D$318,3, FALSE) -> 20 | T8: =VLOOKUP('전체 통계'!$Q8,'하삼주 (251006)'!$A$2:$D$313,3, FALSE) -> 18
B9: 하삼주 | C9: in600 | D9: in400 | E9: in200 | F9: in100 | G9: in50 | K9: 무명 | L9: 150 | M9: 79 | P9: 7 | Q9: 컬러단장용스 | R9: =VLOOKUP('전체 통계'!$Q9,'하삼주(250918)'!$A$2:$D$315,3, FALSE) -> 30 | S9: =VLOOKUP('전체 통계'!$Q9,'하삼주 (250929)'!$A$2:$D$318,3, FALSE) -> 36 | T9: =VLOOKUP('전체 통계'!$Q9,'하삼주 (251006)'!$A$2:$D$313,3, FALSE) -> 32
B10: 무명 | C10: 155 | D10: 113 | E10: 52 | F10: 21 | G10: 9 | K10: 혁명군 | L10: 117 | M10: 54 | P10: 8 | Q10: 이직 | R10: =VLOOKUP('전체 통계'!$Q10,'하삼주(250918)'!$A$2:$D$315,3, FALSE) -> 44 | S10: =VLOOKUP('전체 통계'!$Q10,'하삼주 (250929)'!$A$2:$D$318,3, FALSE) -> 46 | T10: =VLOOKUP('전체 통계'!$Q10,'하삼주 (251006)'!$A$2:$D$313,3, FALSE) -> 38
B11: 혁명군 | C11: 115 | D11: 70 | E11: 23 | F11: 3 | G11: 0 | K11: 관중제장 | L11: 44 | M11: 7 | P11: 9 | Q11: SKELTON | R11: =VLOOKUP('전체 통계'!$Q11,'하삼주(250918)'!$A$2:$D$315,3, FALSE) -> 59 | S11: =VLOOKUP('전체 통계'!$Q11,'하삼주 (250929)'!$A$2:$D$318,3, FALSE) -> 45 | T11: =VLOOKUP('전체 통계'!$Q11,'하삼주 (251006)'!$A$2:$D$313,3, FALSE) -> 43
B12: 관중제장 | C12: 44 | D12: 15 | E12: 1 | F12: 0 | G12: 0 | K12: 251006 | P12: 10 | Q12: 羊양제 | R12: =VLOOKUP('전체 통계'!$Q12,'하삼주(250918)'!$A$2:$D$315,3, FALSE) -> 55 | S12: =VLOOKUP('전체 통계'!$Q12,'하삼주 (250929)'!$A$2:$D$318,3, FALSE) -> 58 | T12: =VLOOKUP('전체 통계'!$Q12,'하삼주 (251006)'!$A$2:$D$313,3, FALSE) -> 48
B13: 귀농단 | C13: 5 | D13: 2 | E13: 0 | F13: 0 | G13: 0 | K13: 동맹 | L13: 전체분포 | M13: in140분포 | P13: 11 | Q13: 羊마산동탁 | R13: =VLOOKUP('전체 통계'!$Q13,'하삼주(250918)'!$A$2:$D$315,3, FALSE) -> 61 | S13: =VLOOKUP('전체 통계'!$Q13,'하삼주 (250929)'!$A$2:$D$318,3, FALSE) -> 53 | T13: =VLOOKUP('전체 통계'!$Q13,'하삼주 (251006)'!$A$2:$D$313,3, FALSE) -> 50
B14: 계 | C14: 319 | D14: 200 | E14: 76 | F14: 24 | G14: 9 | K14: 무명 | L14: 146 | M14: 82 | P14: 12 | Q14: 爛추노꾼 | R14: =VLOOKUP('전체 통계'!$Q14,'하삼주(250918)'!$A$2:$D$315,3, FALSE) -> 47 | S14: =VLOOKUP('전체 통계'!$Q14,'하삼주 (250929)'!$A$2:$D$318,3, FALSE) -> 63 | T14: =VLOOKUP('전체 통계'!$Q14,'하삼주 (251006)'!$A$2:$D$313,3, FALSE) -> 65
B15: 250929 | K15: 혁명군 | L15: 120 | M15: 52 | P15: 13 | Q15: 必우마이봉 | R15: =VLOOKUP('전체 통계'!$Q15,'하삼주(250918)'!$A$2:$D$315,3, FALSE) -> 67 | S15: =VLOOKUP('전체 통계'!$Q15,'하삼주 (250929)'!$A$2:$D$318,3, FALSE) -> 71 | T15: =VLOOKUP('전체 통계'!$Q15,'하삼주 (251006)'!$A$2:$D$313,3, FALSE) -> 71
B16: 상삼주 | C16: in600 | D16: in400 | E16: in200 | F16: in100 | G16: in50 | K16: 관중제장 | L16: 41 | M16: 6 | P16: 16 | Q16: 羊고광렬 | R16: =VLOOKUP('전체 통계'!$Q18,'하삼주(250918)'!$A$2:$D$315,3, FALSE) -> 90 | S16: =VLOOKUP('전체 통계'!$Q18,'하삼주 (250929)'!$A$2:$D$318,3, FALSE) -> 77 | T16: =VLOOKUP('전체 통계'!$Q18,'하삼주 (251006)'!$A$2:$D$313,3, FALSE) -> 75
B17: 잠룡 | C17: 187 | D17: 161 | E17: 113 | F17: 68 | G17: 38 | P17: 14 | Q17: 必리나니 | R17: =VLOOKUP('전체 통계'!$Q16,'하삼주(250918)'!$A$2:$D$315,3, FALSE) -> 92 | S17: =VLOOKUP('전체 통계'!$Q16,'하삼주 (250929)'!$A$2:$D$318,3, FALSE) -> 86 | T17: =VLOOKUP('전체 통계'!$Q16,'하삼주 (251006)'!$A$2:$D$313,3, FALSE) -> 73
B18: 아이돌 | C18: 78 | D18: 41 | E18: 8 | F18: 3 | G18: 0 | P18: 15 | Q18: 凵진라면 | R18: =VLOOKUP('전체 통계'!$Q17,'하삼주(250918)'!$A$2:$D$315,3, FALSE) -> 62 | S18: =VLOOKUP('전체 통계'!$Q17,'하삼주 (250929)'!$A$2:$D$318,3, FALSE) -> 73 | T18: =VLOOKUP('전체 통계'!$Q17,'하삼주 (251006)'!$A$2:$D$313,3, FALSE) -> 74
B19: 협동조합 | C19: 17 | D19: 4 | E19: 0 | F19: 0 | G19: 0 | P19: 17 | Q19: 必비숍 | R19: =VLOOKUP('전체 통계'!$Q19,'하삼주(250918)'!$A$2:$D$315,3, FALSE) -> 111 | S19: =VLOOKUP('전체 통계'!$Q19,'하삼주 (250929)'!$A$2:$D$318,3, FALSE) -> 88 | T19: =VLOOKUP('전체 통계'!$Q19,'하삼주 (251006)'!$A$2:$D$313,3, FALSE) -> 76
B20: 노동조합 | C20: 1 | D20: 0 | E20: 0 | F20: 0 | G20: 0 | P20: 18 | Q20: 羊이정재 | R20: =VLOOKUP('전체 통계'!$Q20,'하삼주(250918)'!$A$2:$D$315,3, FALSE) -> 79 | S20: =VLOOKUP('전체 통계'!$Q20,'하삼주 (250929)'!$A$2:$D$318,3, FALSE) -> 76 | T20: =VLOOKUP('전체 통계'!$Q20,'하삼주 (251006)'!$A$2:$D$313,3, FALSE) -> 78
B21: 계 | C21: 283 | D21: 206 | E21: 121 | F21: 71 | G21: 38 | P21: 19 | Q21: 실직 | R21: =VLOOKUP('전체 통계'!$Q21,'하삼주(250918)'!$A$2:$D$315,3, FALSE) -> 68 | S21: =VLOOKUP('전체 통계'!$Q21,'하삼주 (250929)'!$A$2:$D$318,3, FALSE) -> 99 | T21: =VLOOKUP('전체 통계'!$Q21,'하삼주 (251006)'!$A$2:$D$313,3, FALSE) -> 101 | U21: 하락
B22: 하삼주 | C22: in600 | D22: in400 | E22: in200 | F22: in100 | G22: in50 | P22: 20 | Q22: 必써너 | R22: =VLOOKUP('전체 통계'!$Q22,'하삼주(250918)'!$A$2:$D$315,3, FALSE) -> 144 | S22: =VLOOKUP('전체 통계'!$Q22,'하삼주 (250929)'!$A$2:$D$318,3, FALSE) -> 134 | T22: =VLOOKUP('전체 통계'!$Q22,'하삼주 (251006)'!$A$2:$D$313,3, FALSE) -> 105
B23: 무명 | C23: 150 | D23: 107 | E23: 49 | F23: 20 | G23: 9 | P23: 21 | Q23: 羊현묘 | R23: =VLOOKUP('전체 통계'!$Q23,'하삼주(250918)'!$A$2:$D$315,3, FALSE) -> 85 | S23: =VLOOKUP('전체 통계'!$Q23,'하삼주 (250929)'!$A$2:$D$318,3, FALSE) -> 102 | T23: =VLOOKUP('전체 통계'!$Q23,'하삼주 (251006)'!$A$2:$D$313,3, FALSE) -> 111 | U23: 하락
B24: 혁명군 | C24: 117 | D24: 73 | E24: 27 | F24: 9 | G24: 3 | P24: 22 | Q24: 마룡의숲 | R24: =VLOOKUP('전체 통계'!$Q24,'하삼주(250918)'!$A$2:$D$315,3, FALSE) -> 82 | S24: =VLOOKUP('전체 통계'!$Q24,'하삼주 (250929)'!$A$2:$D$318,3, FALSE) -> 109 | T24: =VLOOKUP('전체 통계'!$Q24,'하삼주 (251006)'!$A$2:$D$313,3, FALSE) -> 121 | U24: 하락
B25: 관중제장 | C25: 44 | D25: 13 | E25: 3 | F25: 0 | G25: 0 | P25: 23 | Q25: 풍악의날 | R25: =VLOOKUP('전체 통계'!$Q25,'하삼주(250918)'!$A$2:$D$315,3, FALSE) -> 153 | S25: =VLOOKUP('전체 통계'!$Q25,'하삼주 (250929)'!$A$2:$D$318,3, FALSE) -> 145 | T25: =VLOOKUP('전체 통계'!$Q25,'하삼주 (251006)'!$A$2:$D$313,3, FALSE) -> 124
B26: 귀농단 | C26: 6 | D26: 1 | E26: 0 | F26: 0 | G26: 0 | P26: 24 | Q26: 너에게날 | R26: =VLOOKUP('전체 통계'!$Q26,'하삼주(250918)'!$A$2:$D$315,3, FALSE) -> 211 | S26: =VLOOKUP('전체 통계'!$Q26,'하삼주 (250929)'!$A$2:$D$318,3, FALSE) -> 143 | T26: =VLOOKUP('전체 통계'!$Q26,'하삼주 (251006)'!$A$2:$D$313,3, FALSE) -> 128 | U26: 범인
B27: 계 | C27: 317 | D27: 194 | E27: 79 | F27: 29 | G27: 12 | P27: 25 | Q27: 必폭주비비 | R27: =VLOOKUP('전체 통계'!$Q27,'하삼주(250918)'!$A$2:$D$315,3, FALSE) -> 123 | S27: =VLOOKUP('전체 통계'!$Q27,'하삼주 (250929)'!$A$2:$D$318,3, FALSE) -> 132 | T27: =VLOOKUP('전체 통계'!$Q27,'하삼주 (251006)'!$A$2:$D$313,3, FALSE) -> 132
B28: 251006 | P28: 26 | Q28: 羊서량철기 | R28: =VLOOKUP('전체 통계'!$Q28,'하삼주(250918)'!$A$2:$D$315,3, FALSE) -> 115 | S28: =VLOOKUP('전체 통계'!$Q28,'하삼주 (250929)'!$A$2:$D$318,3, FALSE) -> 146 | T28: =VLOOKUP('전체 통계'!$Q28,'하삼주 (251006)'!$A$2:$D$313,3, FALSE) -> 137
B29: 상삼주 | C29: in600 | D29: in400 | E29: in200 | F29: in100 | G29: in50 | P29: 29 | Q29: 必억까 | R29: =VLOOKUP('전체 통계'!$Q31,'하삼주(250918)'!$A$2:$D$315,3, FALSE) -> 158 | S29: =VLOOKUP('전체 통계'!$Q31,'하삼주 (250929)'!$A$2:$D$318,3, FALSE) -> 153 | T29: =VLOOKUP('전체 통계'!$Q31,'하삼주 (251006)'!$A$2:$D$313,3, FALSE) -> 150 | U29: 하락
B30: 잠룡 | C30: 188 | D30: 162 | E30: 116 | F30: 68 | G30: 35 | P30: 28 | Q30: 必무이 | R30: =VLOOKUP('전체 통계'!$Q30,'하삼주(250918)'!$A$2:$D$315,3, FALSE) -> 170 | S30: =VLOOKUP('전체 통계'!$Q30,'하삼주 (250929)'!$A$2:$D$318,3, FALSE) -> 148 | T30: =VLOOKUP('전체 통계'!$Q30,'하삼주 (251006)'!$A$2:$D$313,3, FALSE) -> 146
B31: 아이돌 | C31: 80 | D31: 43 | E31: 9 | F31: 3 | G31: 1 | P31: 27 | Q31: 爛해병 | R31: =VLOOKUP('전체 통계'!$Q29,'하삼주(250918)'!$A$2:$D$315,3, FALSE) -> 87 | S31: =VLOOKUP('전체 통계'!$Q29,'하삼주 (250929)'!$A$2:$D$318,3, FALSE) -> 91 | T31: =VLOOKUP('전체 통계'!$Q29,'하삼주 (251006)'!$A$2:$D$313,3, FALSE) -> 142
B32: 협동조합 | C32: 19 | D32: 4 | E32: 0 | F32: 0 | G32: 0 | P32: 30 | Q32: 必보이쓰피싱 | R32: =VLOOKUP('전체 통계'!$Q32,'하삼주(250918)'!$A$2:$D$315,3, FALSE) -> 201 | S32: =VLOOKUP('전체 통계'!$Q32,'하삼주 (250929)'!$A$2:$D$318,3, FALSE) -> 171 | T32: =VLOOKUP('전체 통계'!$Q32,'하삼주 (251006)'!$A$2:$D$313,3, FALSE) -> 151
B33: 노동조합 | C33: 1 | D33: 0 | E33: 0 | F33: 0 | G33: 0 | P33: 31 | Q33: 싸나이흑운 | R33: =VLOOKUP('전체 통계'!$Q33,'하삼주(250918)'!$A$2:$D$315,3, FALSE) -> 132 | S33: =VLOOKUP('전체 통계'!$Q33,'하삼주 (250929)'!$A$2:$D$318,3, FALSE) -> 147 | T33: =VLOOKUP('전체 통계'!$Q33,'하삼주 (251006)'!$A$2:$D$313,3, FALSE) -> 153
B34: 계 | C34: 288 | D34: 209 | E34: 125 | F34: 71 | G34: 36 | P34: 32 | Q34: 폭우의날 | R34: =VLOOKUP('전체 통계'!$Q34,'하삼주(250918)'!$A$2:$D$315,3, FALSE) -> 192 | S34: =VLOOKUP('전체 통계'!$Q34,'하삼주 (250929)'!$A$2:$D$318,3, FALSE) -> 154 | T34: =VLOOKUP('전체 통계'!$Q34,'하삼주 (251006)'!$A$2:$D$313,3, FALSE) -> 156
B35: 하삼주 | C35: in600 | D35: in400 | E35: in200 | F35: in100 | G35: in50 | P35: 33 | Q35: 羊농민 | R35: =VLOOKUP('전체 통계'!$Q35,'하삼주(250918)'!$A$2:$D$315,3, FALSE) -> 137 | S35: =VLOOKUP('전체 통계'!$Q35,'하삼주 (250929)'!$A$2:$D$318,3, FALSE) -> 173 | T35: =VLOOKUP('전체 통계'!$Q35,'하삼주 (251006)'!$A$2:$D$313,3, FALSE) -> 159
B36: 무명 | C36: 146 | D36: 106 | E36: 48 | F36: 18 | G36: 11 | P36: 34 | Q36: 爛밤 | R36: =VLOOKUP('전체 통계'!$Q36,'하삼주(250918)'!$A$2:$D$315,3, FALSE) -> 126 | S36: =VLOOKUP('전체 통계'!$Q36,'하삼주 (250929)'!$A$2:$D$318,3, FALSE) -> 151 | T36: =VLOOKUP('전체 통계'!$Q36,'하삼주 (251006)'!$A$2:$D$313,3, FALSE) -> 161 | U36: 하락
B37: 혁명군 | C37: 120 | D37: 72 | E37: 25 | F37: 11 | G37: 3 | P37: 36 | Q37: 必귀살대 | R37: =VLOOKUP('전체 통계'!$Q38,'하삼주(250918)'!$A$2:$D$315,3, FALSE) -> 146 | S37: =VLOOKUP('전체 통계'!$Q38,'하삼주 (250929)'!$A$2:$D$318,3, FALSE) -> 169 | T37: =VLOOKUP('전체 통계'!$Q38,'하삼주 (251006)'!$A$2:$D$313,3, FALSE) -> 169
B38: 관중제장 | C38: 41 | D38: 12 | E38: 2 | F38: 0 | G38: 0 | P38: 35 | Q38: 헁기싫어 | R38: =VLOOKUP('전체 통계'!$Q37,'하삼주(250918)'!$A$2:$D$315,3, FALSE) -> 166 | S38: =VLOOKUP('전체 통계'!$Q37,'하삼주 (250929)'!$A$2:$D$318,3, FALSE) -> 178 | T38: =VLOOKUP('전체 통계'!$Q37,'하삼주 (251006)'!$A$2:$D$313,3, FALSE) -> 167
B39: 귀농단 | C39: 5 | D39: 1 | E39: 0 | F39: 0 | G39: 0 | P39: 37 | Q39: 주님곁으로 | R39: =VLOOKUP('전체 통계'!$Q39,'하삼주(250918)'!$A$2:$D$315,3, FALSE) -> 220 | S39: =VLOOKUP('전체 통계'!$Q39,'하삼주 (250929)'!$A$2:$D$318,3, FALSE) -> 172 | T39: =VLOOKUP('전체 통계'!$Q39,'하삼주 (251006)'!$A$2:$D$313,3, FALSE) -> 170
B40: 계 | C40: 312 | D40: 191 | E40: 75 | F40: 29 | G40: 14 | P40: 38 | Q40: 기파랑해 | R40: =VLOOKUP('전체 통계'!$Q40,'하삼주(250918)'!$A$2:$D$315,3, FALSE) -> 206 | S40: =VLOOKUP('전체 통계'!$Q40,'하삼주 (250929)'!$A$2:$D$318,3, FALSE) -> 192 | T40: =VLOOKUP('전체 통계'!$Q40,'하삼주 (251006)'!$A$2:$D$313,3, FALSE) -> 172
P41: 39 | Q41: 羊알부장 | R41: =VLOOKUP('전체 통계'!$Q41,'하삼주(250918)'!$A$2:$D$315,3, FALSE) -> 163 | S41: =VLOOKUP('전체 통계'!$Q41,'하삼주 (250929)'!$A$2:$D$318,3, FALSE) -> 175 | T41: =VLOOKUP('전체 통계'!$Q41,'하삼주 (251006)'!$A$2:$D$313,3, FALSE) -> 174
...

Sheet 전체 랭킹 (250918)
D1: 상삼주 | E1: in600 | F1: in400 | G1: in200 | H1: in100 | I1: in50
D2: 잠룡 | E2: =COUNTIF($C$14:$C$613,$D2) -> 191 | F2: =COUNTIF($C$14:$C$413,$D2) -> 165 | G2: =COUNTIF($C$14:$C$213,$D2) -> 117 | H2: =COUNTIF($C$14:$C$113,$D2) -> 74 | I2: =COUNTIF($C$14:$C$63,$D2) -> 41 | O2: 每 | P2: 매 | Q2: 每
D3: 아이돌 | E3: =COUNTIF($C$14:$C$613,$D3) -> 77 | F3: =COUNTIF($C$14:$C$413,$D3) -> 34 | G3: =COUNTIF($C$14:$C$213,$D3) -> 7 | H3: =COUNTIF($C$14:$C$113,$D3) -> 2 | I3: =COUNTIF($C$14:$C$63,$D3) -> 0 | O3: 天威 | P3: 天威 | Q3: 天威
D4: 협동조합 | E4: =COUNTIF($C$14:$C$613,$D4) -> 12 | F4: =COUNTIF($C$14:$C$413,$D4) -> 1 | G4: =COUNTIF($C$14:$C$213,$D4) -> 0 | H4: =COUNTIF($C$14:$C$113,$D4) -> 0 | I4: =COUNTIF($C$14:$C$63,$D4) -> 0 | O4: 丫 | P4: 아 | Q4: 丫
D5: 노동조합 | E5: =COUNTIF($C$14:$C$613,$D5) -> 0 | F5: =COUNTIF($C$14:$C$413,$D5) -> 0 | G5: =COUNTIF($C$14:$C$213,$D5) -> 0 | H5: =COUNTIF($C$14:$C$113,$D5) -> 0 | I5: =COUNTIF($C$14:$C$63,$D5) -> 0 | O5: 乄 | P5: 오 | Q5: 乄
D6: 계 | E6: =SUM(E2:E5) -> 280 | F6: =SUM(F2:F5) -> 200 | G6: =SUM(G2:G5) -> 124 | H6: =SUM(H2:H5) -> 76 | I6: =SUM(I2:I5) -> 41 | O6: 忠義 | P6: 忠義 | Q6: 忠義
D7: 하삼주 | E7: in600 | F7: in400 | G7: in200 | H7: in100 | I7: in50 | O7: 遊興 | P7: 遊興 | Q7: 遊興
D8: 무명 | E8: =COUNTIF($C$14:$C$613,$D8) -> 155 | F8: =COUNTIF($C$14:$C$413,$D8) -> 113 | G8: =COUNTIF($C$14:$C$213,$D8) -> 52 | H8: =COUNTIF($C$14:$C$113,$D8) -> 21 | I8: =COUNTIF($C$14:$C$63,$D8) -> 9 | O8: 亗 | P8: 세 | Q8: 亗
D9: 혁명군 | E9: =COUNTIF($C$14:$C$613,$D9) -> 115 | F9: =COUNTIF($C$14:$C$413,$D9) -> 70 | G9: =COUNTIF($C$14:$C$213,$D9) -> 23 | H9: =COUNTIF($C$14:$C$113,$D9) -> 3 | I9: =COUNTIF($C$14:$C$63,$D9) -> 0 | O9: 凵 | P9: 감 | Q9: 凵
D10: 관중제장 | E10: =COUNTIF($C$14:$C$613,$D10) -> 44 | F10: =COUNTIF($C$14:$C$413,$D10) -> 15 | G10: =COUNTIF($C$14:$C$213,$D10) -> 1 | H10: =COUNTIF($C$14:$C$113,$D10) -> 0 | I10: =COUNTIF($C$14:$C$63,$D10) -> 0
D11: 귀농단 | E11: =COUNTIF($C$14:$C$613,$D11) -> 5 | F11: =COUNTIF($C$14:$C$413,$D11) -> 2 | G11: =COUNTIF($C$14:$C$213,$D11) -> 0 | H11: =COUNTIF($C$14:$C$113,$D11) -> 0 | I11: =COUNTIF($C$14:$C$63,$D11) -> 0
D12: 계 | E12: =SUM(E8:E11) -> 319 | F12: =SUM(F8:F11) -> 200 | G12: =SUM(G8:G11) -> 76 | H12: =SUM(H8:H11) -> 24 | I12: =SUM(I8:I11) -> 9
A13: 랭킹 | B13: 이름 | C13: 동맹
A14: 1 | B14: 이로아 | C14: 잠룡
A15: 2 | B15: 天威아조씨 | C15: 잠룡
A16: 3 | B16: 靑핑돌 | C16: 잠룡
A17: 4 | B17: 황금비 | C17: 잠룡
A18: 5 | B18: 소풍온아모림 | C18: 잠룡
A19: 6 | B19: 돌격사신 | C19: 잠룡
A20: 7 | B20: 출항의날 | C20: 무명
A21: 8 | B21: 붉은윈터 | C21: 잠룡
A22: 9 | B22: 소풍왕정몽규 | C22: 잠룡
A23: 10 | B23: 화요싫어 | C23: 잠룡
A24: 11 | B24: 必블리파파 | C24: 무명
A25: 12 | B25: 흰밤 | C25: 무명
... A613: 600 | B613: 超연격초토화 | C613: 관중제장

Sheet 하삼주(250918)
A1: 이름 | B1: 동맹 | C1: 랭킹 | D1: 진영 순위 | F1: 동맹 | G1: 전체분포 | H1: in140분포
A2: 출항의날 | B2: 무명 | C2: 7 | D2: 1 | F2: 무명 | G2: =COUNTIF($B$2:$B$315,$F2) -> 155 | H2: =COUNTIF($B$2:$B$141,$F2) -> 90
A3: 必블리파파 | B3: 무명 | C3: 11 | D3: 2 | F3: 혁명군 | G3: =COUNTIF($B$2:$B$315,$F3) -> 115 | H3: =COUNTIF($B$2:$B$141,$F3) -> 44
A4: 흰밤 | B4: 무명 | C4: 12 | D4: 3 | F4: 관중제장 | G4: =COUNTIF($B$2:$B$315,$F4) -> 44 | H4: =COUNTIF($B$2:$B$141,$F4) -> 6
A5: 凵너구리 | B5: 무명 | C5: 21 | D5: 4
A6: 퍼플주에고 | B6: 무명 | C6: 22 | D6: 5
A7: 컬러단장용스 | B7: 무명 | C7: 30 | D7: 6 | F7: 출항의날 | G7: =VLOOKUP(F7,A2:D315,1,FALSE) -> 출항의날
A8: 必비트핑 | B8: 무명 | C8: 35 | D8: 7
A9: 이직 | B9: 무명 | C9: 44 | D9: 8
A10: 爛추노꾼 | B10: 무명 | C10: 47 | D10: 9
A11: 羊양제 | B11: 무명 | C11: 55 | D11: 10
A12: SKELTON | B12: 무명 | C12: 59 | D12: 11
A13: 羊마산동탁 | B13: 무명 | C13: 61 | D13: 12
A14: 必리나니 | B14: 무명 | C14: 62 | D14: 13
A15: 必우마이봉 | B15: 무명 | C15: 67 | D15: 14
A16: 실직 | B16: 무명 | C16: 68 | D16: 15
A17: 乄애램 | B17: 혁명군 | C17: 72 | D17: 16
A18: 羊이정재 | B18: 무명 | C18: 79 | D18: 17
A19: 마룡의숲 | B19: 무명 | C19: 82 | D19: 18
... A315: 超연격초토화 | B315: 관중제장 | C315: 600 | D315: 314

Sheet 전체 랭킹 (250929)
D1: 상삼주 | E1: in600 | F1: in400 | G1: in200 | H1: in100 | I1: in50
D2: 잠룡 | E2: =COUNTIF($C$14:$C$613,$D2) -> 187 | F2: =COUNTIF($C$14:$C$413,$D2) -> 161 | G2: =COUNTIF($C$14:$C$213,$D2) -> 113 | H2: =COUNTIF($C$14:$C$113,$D2) -> 68 | I2: =COUNTIF($C$14:$C$63,$D2) -> 38 | O2: 每 | P2: 매 | Q2: 每
D3: 아이돌 | E3: =COUNTIF($C$14:$C$613,$D3) -> 78 | F3: =COUNTIF($C$14:$C$413,$D3) -> 41 | G3: =COUNTIF($C$14:$C$213,$D3) -> 8 | H3: =COUNTIF($C$14:$C$113,$D3) -> 3 | I3: =COUNTIF($C$14:$C$63,$D3) -> 0 | O3: 天威 | P3: 天威 | Q3: 天威
D4: 협동조합 | E4: =COUNTIF($C$14:$C$613,$D4) -> 17 | F4: =COUNTIF($C$14:$C$413,$D4) -> 4 | G4: =COUNTIF($C$14:$C$213,$D4) -> 0 | H4: =COUNTIF($C$14:$C$113,$D4) -> 0 | I4: =COUNTIF($C$14:$C$63,$D4) -> 0 | O4: 丫 | P4: 아 | Q4: 丫
D5: 노동조합 | E5: =COUNTIF($C$14:$C$613,$D5) -> 1 | F5: =COUNTIF($C$14:$C$413,$D5) -> 0 | G5: =COUNTIF($C$14:$C$213,$D5) -> 0 | H5: =COUNTIF($C$14:$C$113,$D5) -> 0 | I5: =COUNTIF($C$14:$C$63,$D5) -> 0 | O5: 乄 | P5: 오 | Q5: 乄
D6: 계 | E6: =SUM(E2:E5) -> 283 | F6: =SUM(F2:F5) -> 206 | G6: =SUM(G2:G5) -> 121 | H6: =SUM(H2:H5) -> 71 | I6: =SUM(I2:I5) -> 38 | O6: 忠義 | P6: 忠義 | Q6: 忠義
D7: 하삼주 | E7: in600 | F7: in400 | G7: in200 | H7: in100 | I7: in50 | O7: 遊興 | P7: 遊興 | Q7: 遊興
D8: 무명 | E8: =COUNTIF($C$14:$C$613,$D8) -> 150 | F8: =COUNTIF($C$14:$C$413,$D8) -> 107 | G8: =COUNTIF($C$14:$C$213,$D8) -> 49 | H8: =COUNTIF($C$14:$C$113,$D8) -> 20 | I8: =COUNTIF($C$14:$C$63,$D8) -> 9 | O8: 亗 | P8: 세 | Q8: 亗
D9: 혁명군 | E9: =COUNTIF($C$14:$C$613,$D9) -> 117 | F9: =COUNTIF($C$14:$C$413,$D9) -> 73 | G9: =COUNTIF($C$14:$C$213,$D9) -> 27 | H9: =COUNTIF($C$14:$C$113,$D9) -> 9 | I9: =COUNTIF($C$14:$C$63,$D9) -> 3 | O9: 凵 | P9: 감 | Q9: 凵
D10: 관중제장 | E10: =COUNTIF($C$14:$C$613,$D10) -> 44 | F10: =COUNTIF($C$14:$C$413,$D10) -> 13 | G10: =COUNTIF($C$14:$C$213,$D10) -> 3 | H10: =COUNTIF($C$14:$C$113,$D10) -> 0 | I10: =COUNTIF($C$14:$C$63,$D10) -> 0
D11: 귀농단 | E11: =COUNTIF($C$14:$C$613,$D11) -> 6 | F11: =COUNTIF($C$14:$C$413,$D11) -> 1 | G11: =COUNTIF($C$14:$C$213,$D11) -> 0 | H11: =COUNTIF($C$14:$C$113,$D11) -> 0 | I11: =COUNTIF($C$14:$C$63,$D11) -> 0
D12: 계 | E12: =SUM(E8:E11) -> 317 | F12: =SUM(F8:F11) -> 194 | G12: =SUM(G8:G11) -> 79 | H12: =SUM(H8:H11) -> 29 | I12: =SUM(I8:I11) -> 12
A13: 랭킹 | B13: 이름 | C13: 동맹
A14: 1 | B14: 天威아조씨 | C14: 잠룡
A15: 2 | B15: 靑핑돌 | C15: 잠룡
A16: 3 | B16: 황금비 | C16: 잠룡
A17: 4 | B17: 이로아 | C17: 잠룡
A18: 5 | B18: 붉은윈터 | C18: 잠룡
A19: 6 | B19: 출항의날 | C19: 무명
A20: 7 | B20: 소풍온아모림 | C20: 잠룡
A21: 8 | B21: 돌격사신 | C21: 잠룡
A22: 9 | B22: 화요싫어 | C22: 잠룡
A23: 10 | B23: 必블리파파 | C23: 무명
A24: 11 | B24: 靑세쥬 | C24: 잠룡
A25: 12 | B25: 凵너구리 | C25: 무명
... A613: 600 | B613: 슈육한날 | C613: 무명

Sheet 하삼주 (250929)
A1: 이름 | B1: 동맹 | C1: 랭킹 | D1: 진영 순위 | F1: 동맹 | G1: 전체분포 | H1: in140분포
A2: 출항의날 | B2: 무명 | C2: 6 | D2: 1 | F2: 무명 | G2: =COUNTIF($B$2:$B$318,$F2) -> 150 | H2: =COUNTIF($B$2:$B$141,$F2) -> 79
A3: 必블리파파 | B3: 무명 | C3: 10 | D3: 2 | F3: 혁명군 | G3: =COUNTIF($B$2:$B$318,$F3) -> 117 | H3: =COUNTIF($B$2:$B$141,$F3) -> 54
A4: 凵너구리 | B4: 무명 | C4: 12 | D4: 3 | F4: 관중제장 | G4: =COUNTIF($B$2:$B$318,$F4) -> 44 | H4: =COUNTIF($B$2:$B$141,$F4) -> 7
A5: 흰밤 | B5: 무명 | C5: 14 | D5: 4 | E5: 컬러단
A6: 퍼플주에고 | B6: 무명 | C6: 19 | D6: 5 | E6: 컬러단
A7: 必비트핑 | B7: 무명 | C7: 20 | D7: 6
A8: 乄애램 | B8: 혁명군 | C8: 23 | D8: 7
A9: 컬러단장용스 | B9: 무명 | C9: 36 | D9: 8 | E9: 컬러단
A10: W레젠디아 | B10: 혁명군 | C10: 38 | D10: 9
A11: W라기 | B11: 혁명군 | C11: 40 | D11: 10
A12: SKELTON | B12: 무명 | C12: 45 | D12: 11
A13: 이직 | B13: 무명 | C13: 46 | D13: 12
A14: 羊마산동탁 | B14: 무명 | C14: 53 | D14: 13
A15: 羊양제 | B15: 무명 | C15: 58 | D15: 14
A16: 爛추노꾼 | B16: 무명 | C16: 63 | D16: 15
A17: 必우마이봉 | B17: 무명 | C17: 71 | D17: 16
A18: 必리나니 | B18: 무명 | C18: 73 | D18: 17
A19: 羊이정재 | B19: 무명 | C19: 76 | D19: 18
A20: 凵진라면 | B20: 무명 | C20: 77 | D20: 19
A21: 麗호우 | B21: 혁명군 | C21: 78 | D21: 20
... A68: 적색의용 | B68: 관중제장 | C68: 183 | D68: 67
A69: 흰밥 | B69: 무명 | C69: 184 | D69: 68 | E69: 컬러단
A70: 羊마속 | B70: 무명 | C70: 186 | D70: 69
A71: GP또또 | B71: 관중제장 | C71: 187 | D71: 70
A72: 羊열하 | B72: 무명 | C72: 189 | D72: 71
A73: 최경주 | B73: 무명 | C73: 191 | D73: 72
A74: 기파랑해 | B74: 무명 | C74: 192 | D74: 73
A75: SP제갈공명 | B75: 혁명군 | C75: 193 | D75: 74
A76: 어른이날 | B76: 무명 | C76: 195 | D76: 75
A77: 싸나이가는길 | B77: 무명 | C77: 196 | D77: 76
A78: Fins | B78: 혁명군 | C78: 197 | D78: 77
A79: Ak동 | B79: 무명 | C79: 198 | D79: 78
A80: 羊관우 | B80: 무명 | C80: 200 | D80: 79
A81: 必인삼 | B81: 무명 | C81: 204 | D81: 80
... A94: 必설리 | B94: 무명 | C94: 223 | D94: 93
A95: 바나나 | B95: 무명 | C95: 224 | D95: 94 | E95: 컬러단
A96: 羊마형 | B96: 무명 | C96: 225 | D96: 95
A97: 멍멍도깨비 | B97: 관중제장 | C97: 226 | D97: 96
A98: 내미시스 | B98: 무명 | C98: 233 | D98: 97
...

Sheet 전체 랭킹 (251006)
D1: 상삼주 | E1: in600 | F1: in400 | G1: in200 | H1: in100 | I1: in50
D2: 잠룡 | E2: =COUNTIF($C$14:$C$613,$D2) -> 188 | F2: =COUNTIF($C$14:$C$413,$D2) -> 162 | G2: =COUNTIF($C$14:$C$213,$D2) -> 116 | H2: =COUNTIF($C$14:$C$113,$D2) -> 68 | I2: =COUNTIF($C$14:$C$63,$D2) -> 35 | O2: 每 | P2: 매 | Q2: 每
D3: 아이돌 | E3: =COUNTIF($C$14:$C$613,$D3) -> 80 | F3: =COUNTIF($C$14:$C$413,$D3) -> 43 | G3: =COUNTIF($C$14:$C$213,$D3) -> 9 | H3: =COUNTIF($C$14:$C$113,$D3) -> 3 | I3: =COUNTIF($C$14:$C$63,$D3) -> 1 | O3: 天威 | P3: 天威 | Q3: 天威
D4: 협동조합 | E4: =COUNTIF($C$14:$C$613,$D4) -> 19 | F4: =COUNTIF($C$14:$C$413,$D4) -> 4 | G4: =COUNTIF($C$14:$C$213,$D4) -> 0 | H4: =COUNTIF($C$14:$C$113,$D4) -> 0 | I4: =COUNTIF($C$14:$C$63,$D4) -> 0 | O4: 丫 | P4: 아 | Q4: 丫
D5: 노동조합 | E5: =COUNTIF($C$14:$C$613,$D5) -> 1 | F5: =COUNTIF($C$14:$C$413,$D5) -> 0 | G5: =COUNTIF($C$14:$C$213,$D5) -> 0 | H5: =COUNTIF($C$14:$C$113,$D5) -> 0 | I5: =COUNTIF($C$14:$C$63,$D5) -> 0 | O5: 乄 | P5: 오 | Q5: 乄
B6: 义 | D6: 계 | E6: =SUM(E2:E5) -> 288 | F6: =SUM(F2:F5) -> 209 | G6: =SUM(G2:G5) -> 125 | H6: =SUM(H2:H5) -> 71 | I6: =SUM(I2:I5) -> 36 | O6: 忠義 | P6: 忠義 | Q6: 忠義
D7: 하삼주 | E7: in600 | F7: in400 | G7: in200 | H7: in100 | I7: in50 | O7: 遊興 | P7: 遊興 | Q7: 遊興
D8: 무명 | E8: =COUNTIF($C$14:$C$613,$D8) -> 146 | F8: =COUNTIF($C$14:$C$413,$D8) -> 106 | G8: =COUNTIF($C$14:$C$213,$D8) -> 48 | H8: =COUNTIF($C$14:$C$113,$D8) -> 18 | I8: =COUNTIF($C$14:$C$63,$D8) -> 11 | O8: 亗 | P8: 세 | Q8: 亗
D9: 혁명군 | E9: =COUNTIF($C$14:$C$613,$D9) -> 120 | F9: =COUNTIF($C$14:$C$413,$D9) -> 72 | G9: =COUNTIF($C$14:$C$213,$D9) -> 25 | H9: =COUNTIF($C$14:$C$113,$D9) -> 11 | I9: =COUNTIF($C$14:$C$63,$D9) -> 3 | O9: 凵 | P9: 감 | Q9: 凵
D10: 관중제장 | E10: =COUNTIF($C$14:$C$613,$D10) -> 41 | F10: =COUNTIF($C$14:$C$413,$D10) -> 12 | G10: =COUNTIF($C$14:$C$213,$D10) -> 2 | H10: =COUNTIF($C$14:$C$113,$D10) -> 0 | I10: =COUNTIF($C$14:$C$63,$D10) -> 0
D11: 귀농단 | E11: =COUNTIF($C$14:$C$613,$D11) -> 5 | F11: =COUNTIF($C$14:$C$413,$D11) -> 1 | G11: =COUNTIF($C$14:$C$213,$D11) -> 0 | H11: =COUNTIF($C$14:$C$113,$D11) -> 0 | I11: =COUNTIF($C$14:$C$63,$D11) -> 0
D12: 계 | E12: =SUM(E8:E11) -> 312 | F12: =SUM(F8:F11) -> 191 | G12: =SUM(G8:G11) -> 75 | H12: =SUM(H8:H11) -> 29 | I12: =SUM(I8:I11) -> 14
A13: 랭킹 | B13: 이름 | C13: 동맹
A14: 1 | B14: 天威아조씨 | C14: 잠룡
A15: 2 | B15: 靑핑돌 | C15: 잠룡
A16: 3 | B16: 황금비 | C16: 잠룡
A17: 4 | B17: 이로아 | C17: 잠룡
A18: 5 | B18: 출항의날 | C18: 무명
A19: 6 | B19: 소풍온아모림 | C19: 잠룡
A20: 7 | B20: 돌격사신 | C20: 잠룡
A21: 8 | B21: 화요싫어 | C21: 잠룡
A22: 9 | B22: 붉은윈터 | C22: 잠룡
A23: 10 | B23: 龍오마카세 | C23: 잠룡
A24: 11 | B24: 凵너구리 | C24: 무명
A25: 12 | B25: 靑세쥬 | C25: 잠룡
... A613: 600 | B613: 하늘물괴기 | C613: 아이돌

Sheet 하삼주 (251006)
A1: 이름 | B1: 동맹 | C1: 랭킹 | D1: 진영 순위 | F1: 동맹 | G1: 전체분포 | H1: in140분포
A2: 출항의날 | B2: 무명 | C2: 5 | D2: 1 | F2: 무명 | G2: =COUNTIF($B$2:$B$313,$F2) -> 145 | H2: =COUNTIF($B$2:$B$61,$F2) -> 35
A3: 凵너구리 | B3: 무명 | C3: 11 | D3: 2 | F3: 혁명군 | G3: =COUNTIF($B$2:$B$313,$F3) -> 120 | H3: =COUNTIF($B$2:$B$61,$F3) -> 23
A4: 必블리파파 | B4: 무명 | C4: 13 | D4: 3 | F4: 관중제장 | G4: =COUNTIF($B$2:$B$313,$F4) -> 41 | H4: =COUNTIF($B$2:$B$61,$F4) -> 2
A5: 퍼플주에고 | B5: 무명 | C5: 14 | D5: 4
A6: 흰밤 | B6: 무명 | C6: 15 | D6: 5
A7: 必비트핑 | B7: 무명 | C7: 18 | D7: 6
A8: 乄애램 | B8: 혁명군 | C8: 20 | D8: 7
A9: W레젠디아 | B9: 혁명군 | C9: 31 | D9: 8
A10: 컬러단장용스 | B10: 무명 | C10: 32 | D10: 9
A11: W라기 | B11: 혁명군 | C11: 37 | D11: 10
A12: 이직 | B12: 무명 | C12: 38 | D12: 11
A13: SKELTON | B13: 무명 | C13: 43 | D13: 12
A14: 羊양제 | B14: 무명 | C14: 48 | D14: 13
A15: 羊마산동탁 | B15: 무명 | C15: 50 | D15: 14
A16: 爛추노꾼 | B16: 무명 | C16: 65 | D16: 15
... A193: 乄탕구리 | B193: 혁명군 | C193: 402 | D193: 192
A194: 무무 | B194: 무명 | C194: 405 | D194: 193 | E194: 주식
A195: 불눈이tv | B195: 무명 | C195: 407 | D195: 194 | E195: 양침
A196: 콥관음병 | B196: 무명 | C196: 408 | D196: 195 | E196: 양침
A197: 乄미리내 | B197: 혁명군 | C197: 409 | D197: 196
A198: 흰방 | B198: 무명 | C198: 411 | D198: 197 | E198: 양침
A199: W취자 | B199: 혁명군 | C199: 413 | D199: 198
A200: Mx야마토 | B200: 관중제장 | C200: 420 | D200: 199
A201: 虎초격차 | B201: 혁명군 | C201: 421 | D201: 200
A202: Mx허갈 | B202: 관중제장 | C202: 422 | D202: 201
A203: 必애리 | B203: 무명 | C203: 423 | D203: 202 | E203: 괴도
A204: 乄옴걸 | B204: 혁명군 | C204: 425 | D204: 203
A205: Beluga | B205: 혁명군 | C205: 426 | D205: 204
A206: 乄목재수비군 | B206: 혁명군 | C206: 428 | D206: 205
A207: 폐월 | B207: 관중제장 | C207: 429 | D207: 206
A208: 羊여름이다 | B208: 무명 | C208: 430 | D208: 207 | E208: 양침
A209: 글램핑 | B209: 무명 | C209: 432 | D209: 208 | E209: 주식
A210: 虎모래성 | B210: 혁명군 | C210: 433 | D210: 209
A211: 광색의용 | B211: 관중제장 | C211: 435 | D211: 210
A212: 乄공터수비군 | B212: 혁명군 | C212: 436 | D212: 211
A213: 금색의용 | B213: 관중제장 | C213: 437 | D213: 212
A214: 눈오던날 | B214: 무명 | C214: 438 | D214: 213 | E214: 날
A215: 성룡 | B215: 무명 | C215: 439 | D215: 214 | E215: 주식
A216: 凵참깨라면 | B216: 무명 | C216: 440 | D216: 215 | E216: 양침
...

Sheet 일간 데이터 변화 관측
AF1: 일간총계 | AG1: 월 | AK1: 화 | AP1: 수 | AU1: 목 | AZ1: 금 | BE1: 토 | BH1: 전체
C2: =SUM(C6:C200)/2 -> 21745246 | D2: =SUM(D6:D200) -> 188868 | E2: =SUM(E6:E200) -> 67599999 | F2: =SUM(F6:F200) -> 297440 | G2: =SUM(G6:G200) -> 24204538 | H2: =SUM(H6:H200) -> 2506807.5 | I2: =SUM(I6:I200) -> 108622 | J2: =SUM(J6:J200) -> 91217520 | K2: =SUM(K6:K200) -> 435626 | ... AA2: =SUM(AA6:AA200) -> 22749926 | AD2: =SUM(AD6:AD200)/7 -> 22969882 | AG2: =SUM(AG6:AG200) -> 22608471 | AK2: =SUM(AK6:AK200) -> 22796141 | AP2: =SUM(AP6:AP200) -> 24270310 | AU2: =SUM(AU6:AU200) -> 21370818 | AZ2: =SUM(AZ6:AZ200) -> 26585527 | BE2: =SUM(BE6:BE200) -> 27861947 | BH2: =AVERAGE(AQ2:BG2) -> 25272764
C4: 251008 0시 | E4: 251009 0시 | J4: 251010 0시 | O4: 251011 0시 | T4: 251012 0시 | Y4: 251013 0시 | AD4: 이번주 총전공 | AG4: 251013 | AI4: 251014 | AN4: 251015 | AS4: 251016 | AX4: 251017 | BC4: 251018 | BH4: 이번주 총전공
A5: 분류 | B5: 회원 | C5: 전공 월화 | D5: 협공이번주 | E5: 전공 이번주 | F5: 협공이번주 | G5: 전공 수 | H5: 전일비 증감 | I5: 협공 변화 | J5: 전공 이번주 | K5: 협공이번주 | L5: 전공 목 | M5: 전일비 증감 | N5: 협공 변화 | O5: 전공 이번주 | P5: 협공이번주 | Q5: 전공 금 | R5: 전일비 증감 | S5: 협공 변화 | T5: 전공 이번주 | U5: 협공이번주 | V5: 전공 토 | W5: 전일비 증감 | X5: 협공 변화 | Y5: 전공 이번주 | Z5: 협공이번주 | AA5: 전공 일 | AB5: 전일비 증감 | AC5: 협공 변화 | AD5: 전공 이번주 | AF5: 회원 | AG5: 전공 월 | AH5: 협공 월 | AI5: 전공 이번주 | AJ5: 협공이번주 | AK5: 전공 화 | AL5: 전일비 증감 | AM5: 협공 변화 | AN5: 전공 이번주 | AO5: 협공이번주 | AP5: 전공 수 | AQ5: 전일비 증감 | AR5: 협공 변화 | AS5: 전공 이번주 | AT5: 협공이번주 | AU5: 전공 목 | AV5: 전일비 증감 | AW5: 협공 변화 | AX5: 전공 이번주 | AY5: 협공이번주 | AZ5: 전공 금 | BA5: 전일비 증감 | BB5: 협공 변화 | BC5: 전공 이번주 | BD5: 협공이번주 | BE5: 전공 토 | BF5: 전일비 증감 | BG5: 협공 변화 | BH5: 전공 이번주
A6: 컬러단 | B6: 퍼플주에고 | C6: =VLOOKUP($B6,'251008_0시'!$A$1:$M$200,4,FALSE) -> 579586 | D6: =VLOOKUP($B6,'251008_0시'!$A$1:$M$200,5,FALSE) -> 0 | E6: =VLOOKUP($B6,'251009_0시'!$A$1:$M$200,4,FALSE) -> 890095 | F6: =VLOOKUP($B6,'251009_0시'!$A$1:$M$200,5,FALSE) -> 125 | G6: =E6-C6 -> 310509 | H6: =G6-(C6/2) -> 20716 | I6: =F6-D6 -> 125 | J6: =VLOOKUP($B6,'251010_0시'!$A$1:$M$200,4,FALSE) -> 1193165 | K6: =VLOOKUP($B6,'251010_0시'!$A$1:$M$200,5,FALSE) -> 1479 | L6: =J6-E6 -> 303070 | M6: =L6-G6 -> -7439 | N6: =K6-F6 -> 1354 | O6: =VLOOKUP($B6,'251011_0시'!$A$1:$M$200,4,FALSE) -> 1459498 | P6: =VLOOKUP($B6,'251011_0시'!$A$1:$M$200,5,FALSE) -> 1479 | Q6: =O6-J6 -> 266333 | R6: =Q6-L6 -> -36737 | S6: =P6-K6 -> 0 | T6: =VLOOKUP($B6,'251012_0시'!$A$1:$M$200,4,FALSE) -> 1780297 | U6: =VLOOKUP($B6,'251012_0시'!$A$1:$M$200,5,FALSE) -> 2169 | V6: =T6-O6 -> 320799 | W6: =V6-Q6 -> 54466 | X6: =U6-P6 -> 690 | Y6: =VLOOKUP($B6,'251013_0시'!$A$1:$M$200,4,FALSE) -> 2037354 | Z6: =VLOOKUP($B6,'251013_0시'!$A$1:$M$200,5,FALSE) -> 2169 | AA6: =Y6-T6 -> 257057 | AB6: =AA6-V6 -> -63742 | AC6: =Z6-U6 -> 0 | AD6: =VLOOKUP($B6,'251013_0시'!$A$1:$M$200,4,FALSE) -> 2037354 | AF6: 퍼플주에고 | AG6: =VLOOKUP($AF6,'251013'!$A$1:$M$200,4,FALSE) -> 330351 | AH6: =VLOOKUP($AF6,'251013'!$A$1:$M$200,5,FALSE) -> 749 | AI6: =VLOOKUP($AF6,'251014'!$A$1:$M$200,4,FALSE) -> 670298 | AJ6: =VLOOKUP($AF6,'251014'!$A$1:$M$200,5,FALSE) -> 1099 | AK6: =AI6-AG6 -> 339947 | AL6: =AK6-AG6 -> 9596 | AM6: =AJ6-AH6 -> 350 | AN6: =VLOOKUP($AF6,'251015'!$A$1:$M$200,4,FALSE) -> 1018569 | AO6: =VLOOKUP($AF6,'251015'!$A$1:$M$200,5,FALSE) -> 1099 | AP6: =AN6-AI6 -> 348271 | AQ6: =AP6-AK6 -> 8324 | AR6: =AO6-AJ6 -> 0 | AS6: =VLOOKUP($AF6,'251016'!$A$1:$M$200,4,FALSE) -> 1339982 | AT6: =VLOOKUP($AF6,'251016'!$A$1:$M$200,5,FALSE) -> 1099 | AU6: =AS6-AN6 -> 321413 | AV6: =AU6-AP6 -> -26858 | AW6: =AT6-AO6 -> 0 | AX6: =VLOOKUP($AF6,'251017'!$A$1:$M$200,4,FALSE) -> 1649119 | AY6: =VLOOKUP($AF6,'251017'!$A$1:$M$200,5,FALSE) -> 1099 | AZ6: =AX6-AS6 -> 309137 | BA6: =AZ6-AU6 -> -12276 | BB6: =AY6-AT6 -> 0 | BC6: =VLOOKUP($AF6,'251018'!$A$1:$M$200,4,FALSE) -> 2013815 | BD6: =VLOOKUP($AF6,'251018'!$A$1:$M$200,5,FALSE) -> 1099 | BE6: =BC6-AX6 -> 364696 | BF6: =BE6-AZ6 -> 55559 | BG6: =BD6-AY6 -> 0 | BH6: =VLOOKUP($AF6,'251018'!$A$1:$M$200,4,FALSE) -> 2013815
A7: 컬러단 | B7: 출항의날 | C7: =VLOOKUP($B7,'251008_0시'!$A$1:$M$200,4,FALSE) -> 484962 | D7: =VLOOKUP($B7,'251008_0시'!$A$1:$M$200,5,FALSE) -> 2250 | E7: =VLOOKUP($B7,'251009_0시'!$A$1:$M$200,4,FALSE) -> 785148 | F7: =VLOOKUP($B7,'251009_0시'!$A$1:$M$200,5,FALSE) -> 4118 | G7: =E7-C7 -> 300186 | H7: =G7-(C7/2) -> 57705 | I7: =F7-D7 -> 1868 | J7: =VLOOKUP($B7,'251010_0시'!$A$1:$M$200,4,FALSE) -> 1115404 | K7: =VLOOKUP($B7,'251010_0시'!$A$1:$M$200,5,FALSE) -> 6341 | L7: =J7-E7 -> 330256 | M7: =L7-G7 -> 30070 | N7: =K7-F7 -> 2223 | O7: =VLOOKUP($B7,'251011_0시'!$A$1:$M$200,4,FALSE) -> 1373166 | P7: =VLOOKUP($B7,'251011_0시'!$A$1:$M$200,5,FALSE) -> 8141 | Q7: =O7-J7 -> 257762 | R7: =Q7-L7 -> -72494 | S7: =P7-K7 -> 1800 | T7: =VLOOKUP($B7,'251012_0시'!$A$1:$M$200,4,FALSE) -> 1594086 | U7: =VLOOKUP($B7,'251012_0시'!$A$1:$M$200,5,FALSE) -> 10841 | V7: =T7-O7 -> 220920 | W7: =V7-Q7 -> -36842 | X7: =U7-P7 -> 2700 | Y7: =VLOOKUP($B7,'251013_0시'!$A$1:$M$200,4,FALSE) -> 1837514 | Z7: =VLOOKUP($B7,'251013_0시'!$A$1:$M$200,5,FALSE) -> 12191 | AA7: =Y7-T7 -> 243428 | AB7: =AA7-V7 -> 22508 | AC7: =Z7-U7 -> 1350 | AD7: =VLOOKUP($B7,'251013_0시'!$A$1:$M$200,4,FALSE) -> 1837514 | AF7: 출항의날 | AG7: =VLOOKUP($AF7,'251013'!$A$1:$M$200,4,FALSE) -> 241211 | AH7: =VLOOKUP($AF7,'251013'!$A$1:$M$200,5,FALSE) -> 2250 | AI7: =VLOOKUP($AF7,'251014'!$A$1:$M$200,4,FALSE) -> 469876 | AJ7: =VLOOKUP($AF7,'251014'!$A$1:$M$200,5,FALSE) -> 5400 | AK7: =AI7-AG7 -> 228665 | AL7: =AK7-AG7 -> -12546 | AM7: =AJ7-AH7 -> 3150 | AN7: =VLOOKUP($AF7,'251015'!$A$1:$M$200,4,FALSE) -> 784321 | AO7: =VLOOKUP($AF7,'251015'!$A$1:$M$200,5,FALSE) -> 9000 | AP7: =AN7-AI7 -> 314445 | AQ7: =AP7-AK7 -> 85780 | AR7: =AO7-AJ7 -> 3600 | AS7: =VLOOKUP($AF7,'251016'!$A$1:$M$200,4,FALSE) -> 1090077 | AT7: =VLOOKUP($AF7,'251016'!$A$1:$M$200,5,FALSE) -> 10350 | AU7: =AS7-AN7 -> 305756 | AV7: =AU7-AP7 -> -8689 | AW7: =AT7-AO7 -> 1350 | AX7: =VLOOKUP($AF7,'251017'!$A$1:$M$200,4,FALSE) -> 1442572 | AY7: =VLOOKUP($AF7,'251017'!$A$1:$M$200,5,FALSE) -> 13050 | AZ7: =AX7-AS7 -> 352495 | BA7: =AZ7-AU7 -> 46739 | BB7: =AY7-AT7 -> 2700 | BC7: =VLOOKUP($AF7,'251018'!$A$1:$M$200,4,FALSE) -> 1763709 | BD7: =VLOOKUP($AF7,'251018'!$A$1:$M$200,5,FALSE) -> 14850 | BE7: =BC7-AX7 -> 321137 | BF7: =BE7-AZ7 -> -31358 | BG7: =BD7-AY7 -> 1800 | BH7: =VLOOKUP($AF7,'251018'!$A$1:$M$200,4,FALSE) -> 1763709
A8: 컬러단 | B8: 컬러단장용스 | C8: =VLOOKUP($B8,'251008_0시'!$A$1:$M$200,4,FALSE) -> 543549 | D8: =VLOOKUP($B8,'251008_0시'!$A$1:$M$200,5,FALSE) -> 350 | E8: =VLOOKUP($B8,'251009_0시'!$A$1:$M$200,4,FALSE) -> 847511 | F8: =VLOOKUP($B8,'251009_0시'!$A$1:$M$200,5,FALSE) -> 350 | G8: =E8-C8 -> 303962 | H8: =G8-(C8/2) -> 32187.5 | I8: =F8-D8 -> 0 | J8: =VLOOKUP($B8,'251010_0시'!$A$1:$M$200,4,FALSE) -> 1083278 | K8: =VLOOKUP($B8,'251010_0시'!$A$1:$M$200,5,FALSE) -> 1609 | L8: =J8-E8 -> 235767 | M8: =L8-G8 -> -68195 | N8: =K8-F8 -> 1259 | O8: =VLOOKUP($B8,'251011_0시'!$A$1:$M$200,4,FALSE) -> 1368716 | P8: =VLOOKUP($B8,'251011_0시'!$A$1:$M$200,5,FALSE) -> 1609 | Q8: =O8-J8 -> 285438 | R8: =Q8-L8 -> 49671 | S8: =P8-K8 -> 0 | T8: =VLOOKUP($B8,'251012_0시'!$A$1:$M$200,4,FALSE) -> 1607213 | U8: =VLOOKUP($B8,'251012_0시'!$A$1:$M$200,5,FALSE) -> 1609 | V8: =T8-O8 -> 238497 | W8: =V8-Q8 -> -46941 | X8: =U8-P8 -> 0 | Y8: =VLOOKUP($B8,'251013_0시'!$A$1:$M$200,4,FALSE) -> 1820685 | Z8: =VLOOKUP($B8,'251013_0시'!$A$1:$M$200,5,FALSE) -> 1959 | AA8: =Y8-T8 -> 213472 | AB8: =AA8-V8 -> -25025 | AC8: =Z8-U8 -> 350 | AD8: =VLOOKUP($B8,'251013_0시'!$A$1:$M$200,4,FALSE) -> 1820685 | AF8: 컬러단장용스 | AG8: =VLOOKUP($AF8,'251013'!$A$1:$M$200,4,FALSE) -> 245960 | AH8: =VLOOKUP($AF8,'251013'!$A$1:$M$200,5,FALSE) -> 0 | AI8: =VLOOKUP($AF8,'251014'!$A$1:$M$200,4,FALSE) -> 525865 | AJ8: =VLOOKUP($AF8,'251014'!$A$1:$M$200,5,FALSE) -> 0 | AK8: =AI8-AG8 -> 279905 | AL8: =AK8-AG8 -> 33945 | AM8: =AJ8-AH8 -> 0 | AN8: =VLOOKUP($AF8,'251015'!$A$1:$M$200,4,FALSE) -> 831829 | AO8: =VLOOKUP($AF8,'251015'!$A$1:$M$200,5,FALSE) -> 0 | AP8: =AN8-AI8 -> 305964 | AQ8: =AP8-AK8 -> 26059 | AR8: =AO8-AJ8 -> 0 | AS8: =VLOOKUP($AF8,'251016'!$A$1:$M$200,4,FALSE) -> 1076326 | AT8: =VLOOKUP($AF8,'251016'!$A$1:$M$200,5,FALSE) -> 0 | AU8: =AS8-AN8 -> 244497 | AV8: =AU8-AP8 -> -61467 | AW8: =AT8-AO8 -> 0 | AX8: =VLOOKUP($AF8,'251017'!$A$1:$M$200,4,FALSE) -> 1321299 | AY8: =VLOOKUP($AF8,'251017'!$A$1:$M$200,5,FALSE) -> 0 | AZ8: =AX8-AS8 -> 244973 | BA8: =AZ8-AU8 -> 476 | BB8: =AY8-AT8 -> 0 | BC8: =VLOOKUP($AF8,'251018'!$A$1:$M$200,4,FALSE) -> 1635689 | BD8: =VLOOKUP($AF8,'251018'!$A$1:$M$200,5,FALSE) -> 0 | BE8: =BC8-AX8 -> 314390 | BF8: =BE8-AZ8 -> 69417 | BG8: =BD8-AY8 -> 0 | BH8: =VLOOKUP($AF8,'251018'!$A$1:$M$200,4,FALSE) -> 1635689
B9: 必비트핑 | C9: =VLOOKUP($B9,'251008_0시'!$A$1:$M$200,4,FALSE) -> 555036 | D9: =VLOOKUP($B9,'251008_0시'!$A$1:$M$200,5,FALSE) -> 0 | E9: =VLOOKUP($B9,'251009_0시'!$A$1:$M$200,4,FALSE) -> 767622 | F9: =VLOOKUP($B9,'251009_0시'!$A$1:$M$200,5,FALSE) -> 0 | G9: =E9-C9 -> 212586 | H9: =G9-(C9/2) -> -64932 | I9: =F9-D9 -> 0 | J9: =VLOOKUP($B9,'251010_0시'!$A$1:$M$200,4,FALSE) -> 1030367 | K9: =VLOOKUP($B9,'251010_0시'!$A$1:$M$200,5,FALSE) -> 394 | L9: =J9-E9 -> 262745 | M9: =L9-G9 -> 50159 | N9: =K9-F9 -> 394 | O9: =VLOOKUP($B9,'251011_0시'!$A$1:$M$200,4,FALSE) -> 1268708 | P9: =VLOOKUP($B9,'251011_0시'!$A$1:$M$200,5,FALSE) -> 394 | Q9: =O9-J9 -> 238341 | R9: =Q9-L9 -> -24404 | S9: =P9-K9 -> 0 | T9: =VLOOKUP($B9,'251012_0시'!$A$1:$M$200,4,FALSE) -> 1524791 | U9: =VLOOKUP($B9,'251012_0시'!$A$1:$M$200,5,FALSE) -> 1144 | V9: =T9-O9 -> 256083 | W9: =V9-Q9 -> 17742 | X9: =U9-P9 -> 750 | Y9: =VLOOKUP($B9,'251013_0시'!$A$1:$M$200,4,FALSE) -> 1811691 | Z9: =VLOOKUP($B9,'251013_0시'!$A$1:$M$200,5,FALSE) -> 1144 | AA9: =Y9-T9 -> 286900 | AB9: =AA9-V9 -> 30817 | AC9: =Z9-U9 -> 0 | AD9: =VLOOKUP($B9,'251013_0시'!$A$1:$M$200,4,FALSE) -> 1811691 | AF9: 흰밤 | AG9: =VLOOKUP($AF9,'251013'!$A$1:$M$200,4,FALSE) -> 209816 | AH9: =VLOOKUP($AF9,'251013'!$A$1:$M$200,5,FALSE) -> 50 | AI9: =VLOOKUP($AF9,'251014'!$A$1:$M$200,4,FALSE) -> 476059 | AJ9: =VLOOKUP($AF9,'251014'!$A$1:$M$200,5,FALSE) -> 400 | AK9: =AI9-AG9 -> 266243 | AL9: =AK9-AG9 -> 56427 | AM9: =AJ9-AH9 -> 350 | AN9: =VLOOKUP($AF9,'251015'!$A$1:$M$200,4,FALSE) -> 739251 | AO9: =VLOOKUP($AF9,'251015'!$A$1:$M$200,5,FALSE) -> 400 | AP9: =AN9-AI9 -> 263192 | AQ9: =AP9-AK9 -> -3051 | AR9: =AO9-AJ9 -> 0 | AS9: =VLOOKUP($AF9,'251016'!$A$1:$M$200,4,FALSE) -> 944140 | AT9: =VLOOKUP($AF9,'251016'!$A$1:$M$200,5,FALSE) -> 400 | AU9: =AS9-AN9 -> 204889 | AV9: =AU9-AP9 -> -58303 | AW9: =AT9-AO9 -> 0 | AX9: =VLOOKUP($AF9,'251017'!$A$1:$M$200,4,FALSE) -> 1260665 | AY9: =VLOOKUP($AF9,'251017'!$A$1:$M$200,5,FALSE) -> 703 | AZ9: =AX9-AS9 -> 316525 | BA9: =AZ9-AU9 -> 111636 | BB9: =AY9-AT9 -> 303 | BC9: =VLOOKUP($AF9,'251018'!$A$1:$M$200,4,FALSE) -> 1576790 | BD9: =VLOOKUP($AF9,'251018'!$A$1:$M$200,5,FALSE) -> 703 | BE9: =BC9-AX9 -> 316125 | BF9: =BE9-AZ9 -> -400 | BG9: =BD9-AY9 -> 0 | BH9: =VLOOKUP($AF9,'251018'!$A$1:$M$200,4,FALSE) -> 1576790
B10: 흰밤 | C10: =VLOOKUP($B10,'251008_0시'!$A$1:$M$200,4,FALSE) -> 555403 | D10: =VLOOKUP($B10,'251008_0시'!$A$1:$M$200,5,FALSE) -> 138 | E10: =VLOOKUP($B10,'251009_0시'!$A$1:$M$200,4,FALSE) -> 830233 | F10: =VLOOKUP($B10,'251009_0시'!$A$1:$M$200,5,FALSE) -> 138 | G10: =E10-C10 -> 274830 | H10: =G10-(C10/2) -> -2871.5 | I10: =F10-D10 -> 0 | J10: =VLOOKUP($B10,'251010_0시'!$A$1:$M$200,4,FALSE) -> 1108677 | K10: =VLOOKUP($B10,'251010_0시'!$A$1:$M$200,5,FALSE) -> 777 | L10: =J10-E10 -> 278444 | M10: =L10-G10 -> 3614 | N10: =K10-F10 -> 639 | O10: =VLOOKUP($B10,'251011_0시'!$A$1:$M$200,4,FALSE) -> 1375719 | P10: =VLOOKUP($B10,'251011_0시'!$A$1:$M$200,5,FALSE) -> 777 | Q10: =O10-J10 -> 267042 | R10: =Q10-L10 -> -11402 | S10: =P10-K10 -> 0 | T10: =VLOOKUP($B10,'251012_0시'!$A$1:$M$200,4,FALSE) -> 1616138 | U10: =VLOOKUP($B10,'251012_0시'!$A$1:$M$200,5,FALSE) -> 777 | V10: =T10-O10 -> 240419 | W10: =V10-Q10 -> -26623 | X10: =U10-P10 -> 0 | Y10: =VLOOKUP($B10,'251013_0시'!$A$1:$M$200,4,FALSE) -> 1800174 | Z10: =VLOOKUP($B10,'251013_0시'!$A$1:$M$200,5,FALSE) -> 777 | AA10: =Y10-T10 -> 184036 | AB10: =AA10-V10 -> -56383 | AC10: =Z10-U10 -> 0 | AD10: =VLOOKUP($B10,'251013_0시'!$A$1:$M$200,4,FALSE) -> 1800174 | AF10: 검정말릭 | AG10: =VLOOKUP($AF10,'251013'!$A$1:$M$200,4,FALSE) -> 228826 | AH10: =VLOOKUP($AF10,'251013'!$A$1:$M$200,5,FALSE) -> 0 | AI10: =VLOOKUP($AF10,'251014'!$A$1:$M$200,4,FALSE) -> 500805 | AJ10: =VLOOKUP($AF10,'251014'!$A$1:$M$200,5,FALSE) -> 0 | AK10: =AI10-AG10 -> 271979 | AL10: =AK10-AG10 -> 43153 | AM10: =AJ10-AH10 -> 0 | AN10: =VLOOKUP($AF10,'251015'!$A$1:$M$200,4,FALSE) -> 731504 | AO10: =VLOOKUP($AF10,'251015'!$A$1:$M$200,5,FALSE) -> 0 | AP10: =AN10-AI10 -> 230699 | AQ10: =AP10-AK10 -> -41280 | AR10: =AO10-AJ10 -> 0 | AS10: =VLOOKUP($AF10,'251016'!$A$1:$M$200,4,FALSE) -> 950077 | AT10: =VLOOKUP($AF10,'251016'!$A$1:$M$200,5,FALSE) -> 0 | AU10: =AS10-AN10 -> 218573 | AV10: =AU10-AP10 -> -12126 | AW10: =AT10-AO10 -> 0 | AX10: =VLOOKUP($AF10,'251017'!$A$1:$M$200,4,FALSE) -> 1260681 | AY10: =VLOOKUP($AF10,'251017'!$A$1:$M$200,5,FALSE) -> 96 | AZ10: =AX10-AS10 -> 310604 | BA10: =AZ10-AU10 -> 92031 | BB10: =AY10-AT10 -> 96 | BC10: =VLOOKUP($AF10,'251018'!$A$1:$M$200,4,FALSE) -> 1535535 | BD10: =VLOOKUP($AF10,'251018'!$A$1:$M$200,5,FALSE) -> 96 | BE10: =BC10-AX10 -> 274854 | BF10: =BE10-AZ10 -> -35750 | BG10: =BD10-AY10 -> 0 | BH10: =VLOOKUP($AF10,'251018'!$A$1:$M$200,4,FALSE) -> 1535535
B11: 株이직 | C11: =VLOOKUP($B11,'251008_0시'!$A$1:$M$200,4,FALSE) -> 531460 | D11: =VLOOKUP($B11,'251008_0시'!$A$1:$M$200,5,FALSE) -> 520 | E11: =VLOOKUP($B11,'251009_0시'!$A$1:$M$200,4,FALSE) -> 789788 | F11: =VLOOKUP($B11,'251009_0시'!$A$1:$M$200,5,FALSE) -> 520 | G11: =E11-C11 -> 258328 | H11: =G11-(C11/2) -> -7402 | I11: =F11-D11 -> 0 | J11: =VLOOKUP($B11,'251010_0시'!$A$1:$M$200,4,FALSE) -> 1027354 | K11: =VLOOKUP($B11,'251010_0시'!$A$1:$M$200,5,FALSE) -> 520 | L11: =J11-E11 -> 237566 | M11: =L11-G11 -> -20762 | N11: =K11-F11 -> 0 | O11: =VLOOKUP($B11,'251011_0시'!$A$1:$M$200,4,FALSE) -> 1226311 | P11: =VLOOKUP($B11,'251011_0시'!$A$1:$M$200,5,FALSE) -> 520 | Q11: =O11-J11 -> 198957 | R11: =Q11-L11 -> -38609 | S11: =P11-K11 -> 0 | T11: =VLOOKUP($B11,'251012_0시'!$A$1:$M$200,4,FALSE) -> 1486101 | U11: =VLOOKUP($B11,'251012_0시'!$A$1:$M$200,5,FALSE) -> 520 | V11: =T11-O11 -> 259790 | W11: =V11-Q11 -> 60833 | X11: =U11-P11 -> 0 | Y11: =VLOOKUP($B11,'251013_0시'!$A$1:$M$200,4,FALSE) -> 1732790 | Z11: =VLOOKUP($B11,'251013_0시'!$A$1:$M$200,5,FALSE) -> 1180 | AA11: =Y11-T11 -> 246689 | AB11: =AA11-V11 -> -13101 | AC11: =Z11-U11 -> 660 | AD11: =VLOOKUP($B11,'251013_0시'!$A$1:$M$200,4,FALSE) -> 1732790 | AF11: 必비숍 | AG11: =VLOOKUP($AF11,'251013'!$A$1:$M$200,4,FALSE) -> 270842 | AH11: =VLOOKUP($AF11,'251013'!$A$1:$M$200,5,FALSE) -> 900 | AI11: =VLOOKUP($AF11,'251014'!$A$1:$M$200,4,FALSE) -> 530177 | AJ11: =VLOOKUP($AF11,'251014'!$A$1:$M$200,5,FALSE) -> 3150 | AK11: =AI11-AG11 -> 259335 | AL11: =AK11-AG11 -> -11507 | AM11: =AJ11-AH11 -> 2250 | AN11: =VLOOKUP($AF11,'251015'!$A$1:$M$200,4,FALSE) -> 784748 | AO11: =VLOOKUP($AF11,'251015'!$A$1:$M$200,5,FALSE) -> 3600 | AP11: =AN11-AI11 -> 254571 | AQ11: =AP11-AK11 -> -4764 | AR11: =AO11-AJ11 -> 450 | AS11: =VLOOKUP($AF11,'251016'!$A$1:$M$200,4,FALSE) -> 1034539 | AT11: =VLOOKUP($AF11,'251016'!$A$1:$M$200,5,FALSE) -> 4500 | AU11: =AS11-AN11 -> 249791 | AV11: =AU11-AP11 -> -4780 | AW11: =AT11-AO11 -> 900 | AX11: =VLOOKUP($AF11,'251017'!$A$1:$M$200,4,FALSE) -> 1244290 | AY11: =VLOOKUP($AF11,'251017'!$A$1:$M$200,5,FALSE) -> 5400 | AZ11: =AX11-AS11 -> 209751 | BA11: =AZ11-AU11 -> -40040 | BB11: =AY11-AT11 -> 900 | BC11: =VLOOKUP($AF11,'251018'!$A$1:$M$200,4,FALSE) -> 1533455 | BD11: =VLOOKUP($AF11,'251018'!$A$1:$M$200,5,FALSE) -> 5850 | BE11: =BC11-AX11 -> 289165 | BF11: =BE11-AZ11 -> 79414 | BG11: =BD11-AY11 -> 450 | BH11: =VLOOKUP($AF11,'251018'!$A$1:$M$200,4,FALSE) -> 1533455
B12: 羊양제 | C12: =VLOOKUP($B12,'251008_0시'!$A$1:$M$200,4,FALSE) -> 514814 | D12: =VLOOKUP($B12,'251008_0시'!$A$1:$M$200,5,FALSE) -> 470 | E12: =VLOOKUP($B12,'251009_0시'!$A$1:$M$200,4,FALSE) -> 790157 | F12: =VLOOKUP($B12,'251009_0시'!$A$1:$M$200,5,FALSE) -> 625 | G12: =E12-C12 -> 275343 | H12: =G12-(C12/2) -> 17936 | I12: =F12-D12 -> 155 | J12: =VLOOKUP($B12,'251010_0시'!$A$1:$M$200,4,FALSE) -> 992565 | K12: =VLOOKUP($B12,'251010_0시'!$A$1:$M$200,5,FALSE) -> 3173 | L12: =J12-E12 -> 202408 | M12: =L12-G12 -> -72935 | N12: =K12-F12 -> 2548 | O12: =VLOOKUP($B12,'251011_0시'!$A$1:$M$200,4,FALSE) -> 1236123 | P12: =VLOOKUP($B12,'251011_0시'!$A$1:$M$200,5,FALSE) -> 5473 | Q12: =O12-J12 -> 243558 | R12: =Q12-L12 -> 41150 | S12: =P12-K12 -> 2300 | T12: =VLOOKUP($B12,'251012_0시'!$A$1:$M$200,4,FALSE) -> 1457313 | U12: =VLOOKUP($B12,'251012_0시'!$A$1:$M$200,5,FALSE) -> 8223 | V12: =T12-O12 -> 221190 | W12: =V12-Q12 -> -22368 | X12: =U12-P12 -> 2750 | Y12: =VLOOKUP($B12,'251013_0시'!$A$1:$M$200,4,FALSE) -> 1692915 | Z12: =VLOOKUP($B12,'251013_0시'!$A$1:$M$200,5,FALSE) -> 8223 | AA12: =Y12-T12 -> 235602 | AB12: =AA12-V12 -> 14412 | AC12: =Z12-U12 -> 0 | AD12: =VLOOKUP($B12,'251013_0시'!$A$1:$M$200,4,FALSE) -> 1692915 | AF12: 羊이정재 | AG12: =VLOOKUP($AF12,'251013'!$A$1:$M$200,4,FALSE) -> 226184 | AH12: =VLOOKUP($AF12,'251013'!$A$1:$M$200,5,FALSE) -> 0 | AI12: =VLOOKUP($AF12,'251014'!$A$1:$M$200,4,FALSE) -> 444448 | AJ12: =VLOOKUP($AF12,'251014'!$A$1:$M$200,5,FALSE) -> 0 | AK12: =AI12-AG12 -> 218264 | AL12: =AK12-AG12 -> -7920 | AM12: =AJ12-AH12 -> 0 | AN12: =VLOOKUP($AF12,'251015'!$A$1:$M$200,4,FALSE) -> 657901 | AO12: =VLOOKUP($AF12,'251015'!$A$1:$M$200,5,FALSE) -> 0 | AP12: =AN12-AI12 -> 213453 | AQ12: =AP12-AK12 -> -4811 | AR12: =AO12-AJ12 -> 0 | AS12: =VLOOKUP($AF12,'251016'!$A$1:$M$200,4,FALSE) -> 890726 | AT12: =VLOOKUP($AF12,'251016'!$A$1:$M$200,5,FALSE) -> 0 | AU12: =AS12-AN12 -> 232825 | AV12: =AU12-AP12 -> 19372 | AW12: =AT12-AO12 -> 0 | AX12: =VLOOKUP($AF12,'251017'!$A$1:$M$200,4,FALSE) -> 1222428 | AY12: =VLOOKUP($AF12,'251017'!$A$1:$M$200,5,FALSE) -> 0 | AZ12: =AX12-AS12 -> 331702 | BA12: =AZ12-AU12 -> 98877 | BB12: =AY12-AT12 -> 0 | BC12: =VLOOKUP($AF12,'251018'!$A$1:$M$200,4,FALSE) -> 1518890 | BD12: =VLOOKUP($AF12,'251018'!$A$1:$M$200,5,FALSE) -> 0 | BE12: =BC12-AX12 -> 296462 | BF12: =BE12-AZ12 -> -35240 | BG12: =BD12-AY12 -> 0 | BH12: =VLOOKUP($AF12,'251018'!$A$1:$M$200,4,FALSE) -> 1518890
B13: 凵너구리 | C13: =VLOOKUP($B13,'251008_0시'!$A$1:$M$200,4,FALSE) -> 457051 | D13: =VLOOKUP($B13,'251008_0시'!$A$1:$M$200,5,FALSE) -> 3500 | E13: =VLOOKUP($B13,'251009_0시'!$A$1:$M$200,4,FALSE) -> 687373 | F13: =VLOOKUP($B13,'251009_0시'!$A$1:$M$200,5,FALSE) -> 3640 | G13: =E13-C13 -> 230322 | H13: =G13-(C13/2) -> 1796.5 | I13: =F13-D13 -> 140 | J13: =VLOOKUP($B13,'251010_0시'!$A$1:$M$200,4,FALSE) -> 920962 | K13: =VLOOKUP($B13,'251010_0시'!$A$1:$M$200,5,FALSE) -> 4448 | L13: =J13-E13 -> 233589 | M13: =L13-G13 -> 3267 | N13: =K13-F13 -> 808 | O13: =VLOOKUP($B13,'251011_0시'!$A$1:$M$200,4,FALSE) -> 1172448 | P13: =VLOOKUP($B13,'251011_0시'!$A$1:$M$200,5,FALSE) -> 4448 | Q13: =O13-J13 -> 251486 | R13: =Q13-L13 -> 17897 | S13: =P13-K13 -> 0 | T13: =VLOOKUP($B13,'251012_0시'!$A$1:$M$200,4,FALSE) -> 1422270 | U13: =VLOOKUP($B13,'251012_0시'!$A$1:$M$200,5,FALSE) -> 4448 | V13: =T13-O13 -> 249822 | W13: =V13-Q13 -> -1664 | X13: =U13-P13 -> 0 | Y13: =VLOOKUP($B13,'251013_0시'!$A$1:$M$200,4,FALSE) -> 1655021 | Z13: =VLOOKUP($B13,'251013_0시'!$A$1:$M$200,5,FALSE) -> 4448 | AA13: =Y13-T13 -> 232751 | AB13: =AA13-V13 -> -17071 | AC13: =Z13-U13 -> 0 | AD13: =VLOOKUP($B13,'251013_0시'!$A$1:$M$200,4,FALSE) -> 1655021 | AF13: 羊양제 | AG13: =VLOOKUP($AF13,'251013'!$A$1:$M$200,4,FALSE) -> 240761 | AH13: =VLOOKUP($AF13,'251013'!$A$1:$M$200,5,FALSE) -> 958 | AI13: =VLOOKUP($AF13,'251014'!$A$1:$M$200,4,FALSE) -> 488489 | AJ13: =VLOOKUP($AF13,'251014'!$A$1:$M$200,5,FALSE) -> 958 | AK13: =AI13-AG13 -> 247728 | AL13: =AK13-AG13 -> 6967 | AM13: =AJ13-AH13 -> 0 | AN13: =VLOOKUP($AF13,'251015'!$A$1:$M$200,4,FALSE) -> 731367 | AO13: =VLOOKUP($AF13,'251015'!$A$1:$M$200,5,FALSE) -> 1078 | AP13: =AN13-AI13 -> 242878 | AQ13: =AP13-AK13 -> -4850 | AR13: =AO13-AJ13 -> 120 | AS13: =VLOOKUP($AF13,'251016'!$A$1:$M$200,4,FALSE) -> 938663 | AT13: =VLOOKUP($AF13,'251016'!$A$1:$M$200,5,FALSE) -> 1078 | AU13: =AS13-AN13 -> 207296 | AV13: =AU13-AP13 -> -35582 | AW13: =AT13-AO13 -> 0 | AX13: =VLOOKUP($AF13,'251017'!$A$1:$M$200,4,FALSE) -> 1239641 | AY13: =VLOOKUP($AF13,'251017'!$A$1:$M$200,5,FALSE) -> 1536 | AZ13: =AX13-AS13 -> 300978 | BA13: =AZ13-AU13 -> 93682 | BB13: =AY13-AT13 -> 458 | BC13: =VLOOKUP($AF13,'251018'!$A$1:$M$200,4,FALSE) -> 1485624 | BD13: =VLOOKUP($AF13,'251018'!$A$1:$M$200,5,FALSE) -> 1536 | BE13: =BC13-AX13 -> 245983 | BF13: =BE13-AZ13 -> -54995 | BG13: =BD13-AY13 -> 0 | BH13: =VLOOKUP($AF13,'251018'!$A$1:$M$200,4,FALSE) -> 1485624
B14: SKELTON | C14: =VLOOKUP($B14,'251008_0시'!$A$1:$M$200,4,FALSE) -> 409228 | D14: =VLOOKUP($B14,'251008_0시'!$A$1:$M$200,5,FALSE) -> 350 | E14: =VLOOKUP($B14,'251009_0시'!$A$1:$M$200,4,FALSE) -> 637483 | F14: =VLOOKUP($B14,'251009_0시'!$A$1:$M$200,5,FALSE) -> 700 | G14: =E14-C14 -> 228255 | H14: =G14-(C14/2) -> 23641 | I14: =F14-D14 -> 350 | J14: =VLOOKUP($B14,'251010_0시'!$A$1:$M$200,4,FALSE) -> 887843 | K14: =VLOOKUP($B14,'251010_0시'!$A$1:$M$200,5,FALSE) -> 1301 | L14: =J14-E14 -> 250360 | M14: =L14-G14 -> 22105 | N14: =K14-F14 -> 601 | O14: =VLOOKUP($B14,'251011_0시'!$A$1:$M$200,4,FALSE) -> 1113946 | P14: =VLOOKUP($B14,'251011_0시'!$A$1:$M$200,5,FALSE) -> 1301 | Q14: =O14-J14 -> 226103 | R14: =Q14-L14 -> -24257 | S14: =P14-K14 -> 0 | T14: =VLOOKUP($B14,'251012_0시'!$A$1:$M$200,4,FALSE) -> 1338358 | U14: =VLOOKUP($B14,'251012_0시'!$A$1:$M$200,5,FALSE) -> 1483 | V14: =T14-O14 -> 224412 | W14: =V14-Q14 -> -1691 | X14: =U14-P14 -> 182 | Y14: =VLOOKUP($B14,'251013_0시'!$A$1:$M$200,4,FALSE) -> 1582668 | Z14: =VLOOKUP($B14,'251013_0시'!$A$1:$M$200,5,FALSE) -> 1579 | AA14: =Y14-T14 -> 244310 | AB14: =AA14-V14 -> 19898 | AC14: =Z14-U14 -> 96 | AD14: =VLOOKUP($B14,'251013_0시'!$A$1:$M$200,4,FALSE) -> 1582668 | AF14: 凵너구리 | AG14: =VLOOKUP($AF14,'251013'!$A$1:$M$200,4,FALSE) -> 236758 | AH14: =VLOOKUP($AF14,'251013'!$A$1:$M$200,5,FALSE) -> 700 | AI14: =VLOOKUP($AF14,'251014'!$A$1:$M$200,4,FALSE) -> 495420 | AJ14: =VLOOKUP($AF14,'251014'!$A$1:$M$200,5,FALSE) -> 700 | AK14: =AI14-AG14 -> 258662 | AL14: =AK14-AG14 -> 21904 | AM14: =AJ14-AH14 -> 0 | AN14: =VLOOKUP($AF14,'251015'!$A$1:$M$200,4,FALSE) -> 728959 | AO14: =VLOOKUP($AF14,'251015'!$A$1:$M$200,5,FALSE) -> 1104 | AP14: =AN14-AI14 -> 233539 | AQ14: =AP14-AK14 -> -25123 | AR14: =AO14-AJ14 -> 404 | AS14: =VLOOKUP($AF14,'251016'!$A$1:$M$200,4,FALSE) -> 984227 | AT14: =VLOOKUP($AF14,'251016'!$A$1:$M$200,5,FALSE) -> 1104 | AU14: =AS14-AN14 -> 255268 | AV14: =AU14-AP14 -> 21729 | AW14: =AT14-AO14 -> 0 | AX14: =VLOOKUP($AF14,'251017'!$A$1:$M$200,4,FALSE) -> 1230210 | AY14: =VLOOKUP($AF14,'251017'!$A$1:$M$200,5,FALSE) -> 1205 | AZ14: =AX14-AS14 -> 245983 | BA14: =AZ14-AU14 -> -9285 | BB14: =AY14-AT14 -> 101 | BC14: =VLOOKUP($AF14,'251018'!$A$1:$M$200,4,FALSE) -> 1477503 | BD14: =VLOOKUP($AF14,'251018'!$A$1:$M$200,5,FALSE) -> 1205 | BE14: =BC14-AX14 -> 247293 | BF14: =BE14-AZ14 -> 1310 | BG14: =BD14-AY14 -> 0 | BH14: =VLOOKUP($AF14,'251018'!$A$1:$M$200,4,FALSE) -> 1477503
B15: 必블리파파 | C15: =VLOOKUP($B15,'251008_0시'!$A$1:$M$200,4,FALSE) -> 440239 | D15: =VLOOKUP($B15,'251008_0시'!$A$1:$M$200,5,FALSE) -> 0 | E15: =VLOOKUP($B15,'251009_0시'!$A$1:$M$200,4,FALSE) -> 548384 | F15: =VLOOKUP($B15,'251009_0시'!$A$1:$M$200,5,FALSE) -> 0 | G15: =E15-C15 -> 108145 | H15: =G15-(C15/2) -> -111974.5 | I15: =F15-D15 -> 0 | J15: =VLOOKUP($B15,'251010_0시'!$A$1:$M$200,4,FALSE) -> 845354 | K15: =VLOOKUP($B15,'251010_0시'!$A$1:$M$200,5,FALSE) -> 0 | L15: =J15-E15 -> 296970 | M15: =L15-G15 -> 188825 | N15: =K15-F15 -> 0 | O15: =VLOOKUP($B15,'251011_0시'!$A$1:$M$200,4,FALSE) -> 1067955 | P15: =VLOOKUP($B15,'251011_0시'!$A$1:$M$200,5,FALSE) -> 350 | Q15: =O15-J15 -> 222601 | R15: =Q15-L15 -> -74369 | S15: =P15-K15 -> 350 | T15: =VLOOKUP($B15,'251012_0시'!$A$1:$M$200,4,FALSE) -> 1300582 | U15: =VLOOKUP($B15,'251012_0시'!$A$1:$M$200,5,FALSE) -> 350 | V15: =T15-O15 -> 232627 | W15: =V15-Q15 -> 10026 | X15: =U15-P15 -> 0 | Y15: =VLOOKUP($B15,'251013_0시'!$A$1:$M$200,4,FALSE) -> 1533140 | Z15: =VLOOKUP($B15,'251013_0시'!$A$1:$M$200,5,FALSE) -> 350 | AA15: =Y15-T15 -> 232558 | AB15: =AA15-V15 -> -69 | AC15: =Z15-U15 -> 0 | AD15: =VLOOKUP($B15,'251013_0시'!$A$1:$M$200,4,FALSE) -> 1533140 | AF15: 必블리파파 | AG15: =VLOOKUP($AF15,'251013'!$A$1:$M$200,4,FALSE) -> 205283 | AH15: =VLOOKUP($AF15,'251013'!$A$1:$M$200,5,FALSE) -> 0 | AI15: =VLOOKUP($AF15,'251014'!$A$1:$M$200,4,FALSE) -> 423932 | AJ15: =VLOOKUP($AF15,'251014'!$A$1:$M$200,5,FALSE) -> 350 | AK15: =AI15-AG15 -> 218649 | AL15: =AK15-AG15 -> 13366 | AM15: =AJ15-AH15 -> 350 | AN15: =VLOOKUP($AF15,'251015'!$A$1:$M$200,4,FALSE) -> 659101 | AO15: =VLOOKUP($AF15,'251015'!$A$1:$M$200,5,FALSE) -> 350 | AP15: =AN15-AI15 -> 235169 | AQ15: =AP15-AK15 -> 16520 | AR15: =AO15-AJ15 -> 0 | AS15: =VLOOKUP($AF15,'251016'!$A$1:$M$200,4,FALSE) -> 872104 | AT15: =VLOOKUP($AF15,'251016'!$A$1:$M$200,5,FALSE) -> 350 | AU15: =AS15-AN15 -> 213003 | AV15: =AU15-AP15 -> -22166 | AW15: =AT15-AO15 -> 0 | AX15: =VLOOKUP($AF15,'251017'!$A$1:$M$200,4,FALSE) -> 1183489 | AY15: =VLOOKUP($AF15,'251017'!$A$1:$M$200,5,FALSE) -> 350 | AZ15: =AX15-AS15 -> 311385 | BA15: =AZ15-AU15 -> 98382 | BB15: =AY15-AT15 -> 0 | BC15: =VLOOKUP($AF15,'251018'!$A$1:$M$200,4,FALSE) -> 1414973 | BD15: =VLOOKUP($AF15,'251018'!$A$1:$M$200,5,FALSE) -> 350 | BE15: =BC15-AX15 -> 231484 | BF15: =BE15-AZ15 -> -79901 | BG15: =BD15-AY15 -> 0 | BH15: =VLOOKUP($AF15,'251018'!$A$1:$M$200,4,FALSE) -> 1414973
B16: 검정말릭 | C16: =VLOOKUP($B16,'251008_0시'!$A$1:$M$200,4,FALSE) -> 426077 | D16: =VLOOKUP($B16,'251008_0시'!$A$1:$M$200,5,FALSE) -> 0 | E16: =VLOOKUP($B16,'251009_0시'!$A$1:$M$200,4,FALSE) -> 645839 | F16: =VLOOKUP($B16,'251009_0시'!$A$1:$M$200,5,FALSE) -> 350 | G16: =E16-C16 -> 219762 | H16: =G16-(C16/2) -> 6723.5 | I16: =F16-D16 -> 350 | J16: =VLOOKUP($B16,'251010_0시'!$A$1:$M$200,4,FALSE) -> 840484 | K16: =VLOOKUP($B16,'251010_0시'!$A$1:$M$200,5,FALSE) -> 350 | L16: =J16-E16 -> 194645 | M16: =L16-G16 -> -25117 | N16: =K16-F16 -> 0 | O16: =VLOOKUP($B16,'251011_0시'!$A$1:$M$200,4,FALSE) -> 1049062 | P16: =VLOOKUP($B16,'251011_0시'!$A$1:$M$200,5,FALSE) -> 350 | Q16: =O16-J16 -> 208578 | R16: =Q16-L16 -> 13933 | S16: =P16-K16 -> 0 | T16: =VLOOKUP($B16,'251012_0시'!$A$1:$M$200,4,FALSE) -> 1315742 | U16: =VLOOKUP($B16,'251012_0시'!$A$1:$M$200,5,FALSE) -> 350 | V16: =T16-O16 -> 266680 | W16: =V16-Q16 -> 58102 | X16: =U16-P16 -> 0 | Y16: =VLOOKUP($B16,'251013_0시'!$A$1:$M$200,4,FALSE) -> 1518801 | Z16: =VLOOKUP($B16,'251013_0시'!$A$1:$M$200,5,FALSE) -> 400 | AA16: =Y16-T16 -> 203059 | AB16: =AA16-V16 -> -63621 | AC16: =Z16-U16 -> 50 | AD16: =VLOOKUP($B16,'251013_0시'!$A$1:$M$200,4,FALSE) -> 1518801 | AF16: 羊마산동탁 | AG16: =VLOOKUP($AF16,'251013'!$A$1:$M$200,4,FALSE) -> 222477 | AH16: =VLOOKUP($AF16,'251013'!$A$1:$M$200,5,FALSE) -> 4106 | AI16: =VLOOKUP($AF16,'251014'!$A$1:$M$200,4,FALSE) -> 451678 | AJ16: =VLOOKUP($AF16,'251014'!$A$1:$M$200,5,FALSE) -> 6356 | AK16: =AI16-AG16 -> 229201 | AL16: =AK16-AG16 -> 6724 | AM16: =AJ16-AH16 -> 2250 | AN16: =VLOOKUP($AF16,'251015'!$A$1:$M$200,4,FALSE) -> 670902 | AO16: =VLOOKUP($AF16,'251015'!$A$1:$M$200,5,FALSE) -> 9506 | AP16: =AN16-AI16 -> 219224 | AQ16: =AP16-AK16 -> -9977 | AR16: =AO16-AJ16 -> 3150 | AS16: =VLOOKUP($AF16,'251016'!$A$1:$M$200,4,FALSE) -> 914654 | AT16: =VLOOKUP($AF16,'251016'!$A$1:$M$200,5,FALSE) -> 13106 | AU16: =AS16-AN16 -> 243752 | AV16: =AU16-AP16 -> 24528 | AW16: =AT16-AO16 -> 3600 | AX16: =VLOOKUP($AF16,'251017'!$A$1:$M$200,4,FALSE) -> 1171251 | AY16: =VLOOKUP($AF16,'251017'!$A$1:$M$200,5,FALSE) -> 15108 | AZ16: =AX16-AS16 -> 256597 | BA16: =AZ16-AU16 -> 12845 | BB16: =AY16-AT16 -> 2002 | BC16: =VLOOKUP($AF16,'251018'!$A$1:$M$200,4,FALSE) -> 1413994 | BD16: =VLOOKUP($AF16,'251018'!$A$1:$M$200,5,FALSE) -> 16908 | BE16: =BC16-AX16 -> 242743 | BF16: =BE16-AZ16 -> -13854 | BG16: =BD16-AY16 -> 1800 | BH16: =VLOOKUP($AF16,'251018'!$A$1:$M$200,4,FALSE) -> 1413994
A17: 컬러단 | B17: 必써너 | C17: =VLOOKUP($B17,'251008_0시'!$A$1:$M$200,4,FALSE) -> 419817 | D17: =VLOOKUP($B17,'251008_0시'!$A$1:$M$200,5,FALSE) -> 5591 | E17: =VLOOKUP($B17,'251009_0시'!$A$1:$M$200,4,FALSE) -> 663717 | F17: =VLOOKUP($B17,'251009_0시'!$A$1:$M$200,5,FALSE) -> 8568 | G17: =E17-C17 -> 243900 | H17: =G17-(C17/2) -> 33991.5 | I17: =F17-D17 -> 2977 | J17: =VLOOKUP($B17,'251010_0시'!$A$1:$M$200,4,FALSE) -> 909199 | K17: =VLOOKUP($B17,'251010_0시'!$A$1:$M$200,5,FALSE) -> 10403 | L17: =J17-E17 -> 245482 | M17: =L17-G17 -> 1582 | N17: =K17-F17 -> 1835 | O17: =VLOOKUP($B17,'251011_0시'!$A$1:$M$200,4,FALSE) -> 1091850 | P17: =VLOOKUP($B17,'251011_0시'!$A$1:$M$200,5,FALSE) -> 13103 | Q17: =O17-J17 -> 182651 | R17: =Q17-L17 -> -62831 | S17: =P17-K17 -> 2700 | T17: =VLOOKUP($B17,'251012_0시'!$A$1:$M$200,4,FALSE) -> 1300255 | U17: =VLOOKUP($B17,'251012_0시'!$A$1:$M$200,5,FALSE) -> 15353 | V17: =T17-O17 -> 208405 | W17: =V17-Q17 -> 25754 | X17: =U17-P17 -> 2250 | Y17: =VLOOKUP($B17,'251013_0시'!$A$1:$M$200,4,FALSE) -> 1509806 | Z17: =VLOOKUP($B17,'251013_0시'!$A$1:$M$200,5,FALSE) -> 18503 | AA17: =Y17-T17 -> 209551 | AB17: =AA17-V17 -> 1146 | AC17: =Z17-U17 -> 3150 | AD17: =VLOOKUP($B17,'251013_0시'!$A$1:$M$200,4,FALSE) -> 1509806 | AF17: SKELTON | AG17: =VLOOKUP($AF17,'251013'!$A$1:$M$200,4,FALSE) -> 212143 | AH17: =VLOOKUP($AF17,'251013'!$A$1:$M$200,5,FALSE) -> 531 | AI17: =VLOOKUP($AF17,'251014'!$A$1:$M$200,4,FALSE) -> 428909 | AJ17: =VLOOKUP($AF17,'251014'!$A$1:$M$200,5,FALSE) -> 531 | AK17: =AI17-AG17 -> 216766 | AL17: =AK17-AG17 -> 4623 | AM17: =AJ17-AH17 -> 0 | AN17: =VLOOKUP($AF17,'251015'!$A$1:$M$200,4,FALSE) -> 628447 | AO17: =VLOOKUP($AF17,'251015'!$A$1:$M$200,5,FALSE) -> 531 | AP17: =AN17-AI17 -> 199538 | AQ17: =AP17-AK17 -> -17228 | AR17: =AO17-AJ17 -> 0 | AS17: =VLOOKUP($AF17,'251016'!$A$1:$M$200,4,FALSE) -> 832213 | AT17: =VLOOKUP($AF17,'251016'!$A$1:$M$200,5,FALSE) -> 531 | AU17: =AS17-AN17 -> 203766 | AV17: =AU17-AP17 -> 4228 | AW17: =AT17-AO17 -> 0 | AX17: =VLOOKUP($AF17,'251017'!$A$1:$M$200,4,FALSE) -> 1087080 | AY17: =VLOOKUP($AF17,'251017'!$A$1:$M$200,5,FALSE) -> 531 | AZ17: =AX17-AS17 -> 254867 | BA17: =AZ17-AU17 -> 51101 | BB17: =AY17-AT17 -> 0 | BC17: =VLOOKUP($AF17,'251018'!$A$1:$M$200,4,FALSE) -> 1353348 | BD17: =VLOOKUP($AF17,'251018'!$A$1:$M$200,5,FALSE) -> 531 | BE17: =BC17-AX17 -> 266268 | BF17: =BE17-AZ17 -> 11401 | BG17: =BD17-AY17 -> 0 | BH17: =VLOOKUP($AF17,'251018'!$A$1:$M$200,4,FALSE) -> 1353348
B18: 必비숍 | C18: =VLOOKUP($B18,'251008_0시'!$A$1:$M$200,4,FALSE) -> 433183 | D18: =VLOOKUP($B18,'251008_0시'!$A$1:$M$200,5,FALSE) -> 1920 | E18: =VLOOKUP($B18,'251009_0시'!$A$1:$M$200,4,FALSE) -> 634083 | F18: =VLOOKUP($B18,'251009_0시'!$A$1:$M$200,5,FALSE) -> 2640 | G18: =E18-C18 -> 200900 | H18: =G18-(C18/2) -> -15691.5 | I18: =F18-D18 -> 720 | J18: =VLOOKUP($B18,'251010_0시'!$A$1:$M$200,4,FALSE) -> 843871 | K18: =VLOOKUP($B18,'251010_0시'!$A$1:$M$200,5,FALSE) -> 2962 | L18: =J18-E18 -> 209788 | M18: =L18-G18 -> 8888 | N18: =K18-F18 -> 322 | O18: =VLOOKUP($B18,'251011_0시'!$A$1:$M$200,4,FALSE) -> 1062980 | P18: =VLOOKUP($B18,'251011_0시'!$A$1:$M$200,5,FALSE) -> 2962 | Q18: =O18-J18 -> 219109 | R18: =Q18-L18 -> 9321 | S18: =P18-K18 -> 0 | T18: =VLOOKUP($B18,'251012_0시'!$A$1:$M$200,4,FALSE) -> 1273253 | U18: =VLOOKUP($B18,'251012_0시'!$A$1:$M$200,5,FALSE) -> 3862 | V18: =T18-O18 -> 210273 | W18: =V18-Q18 -> -8836 | X18: =U18-P18 -> 900 | Y18: =VLOOKUP($B18,'251013_0시'!$A$1:$M$200,4,FALSE) -> 1480984 | Z18: =VLOOKUP($B18,'251013_0시'!$A$1:$M$200,5,FALSE) -> 4762 | AA18: =Y18-T18 -> 207731 | AB18: =AA18-V18 -> -2542 | AC18: =Z18-U18 -> 900 | AD18: =VLOOKUP($B18,'251013_0시'!$A$1:$M$200,4,FALSE) -> 1480984 | AF18: 凵무파마 | AG18: =VLOOKUP($AF18,'251013'!$A$1:$M$200,4,FALSE) -> 113875 | AH18: =VLOOKUP($AF18,'251013'!$A$1:$M$200,5,FALSE) -> 0 | AI18: =VLOOKUP($AF18,'251014'!$A$1:$M$200,4,FALSE) -> 316972 | AJ18: =VLOOKUP($AF18,'251014'!$A$1:$M$200,5,FALSE) -> 0 | AK18: =AI18-AG18 -> 203097 | AL18: =AK18-AG18 -> 89222 | AM18: =AJ18-AH18 -> 0 | AN18: =VLOOKUP($AF18,'251015'!$A$1:$M$200,4,FALSE) -> 575131 | AO18: =VLOOKUP($AF18,'251015'!$A$1:$M$200,5,FALSE) -> 50 | AP18: =AN18-AI18 -> 258159 | AQ18: =AP18-AK18 -> 55062 | AR18: =AO18-AJ18 -> 50 | AS18: =VLOOKUP($AF18,'251016'!$A$1:$M$200,4,FALSE) -> 784311 | AT18: =VLOOKUP($AF18,'251016'!$A$1:$M$200,5,FALSE) -> 50 | AU18: =AS18-AN18 -> 209180 | AV18: =AU18-AP18 -> -48979 | AW18: =AT18-AO18 -> 0 | AX18: =VLOOKUP($AF18,'251017'!$A$1:$M$200,4,FALSE) -> 1075548 | AY18: =VLOOKUP($AF18,'251017'!$A$1:$M$200,5,FALSE) -> 50 | AZ18: =AX18-AS18 -> 291237 | BA18: =AZ18-AU18 -> 82057 | BB18: =AY18-AT18 -> 0 | BC18: =VLOOKUP($AF18,'251018'!$A$1:$M$200,4,FALSE) -> 1339632 | BD18: =VLOOKUP($AF18,'251018'!$A$1:$M$200,5,FALSE) -> 50 | BE18: =BC18-AX18 -> 264084 | BF18: =BE18-AZ18 -> -27153 | BG18: =BD18-AY18 -> 0 | BH18: =VLOOKUP($AF18,'251018'!$A$1:$M$200,4,FALSE) -> 1339632
